[2025-03-03T12:54:51.136+0000] {taskinstance.py:1157} INFO - Dependencies all met for dep_context=non-requeueable deps ti=<TaskInstance: xkcd_dbt_transformations.dbt_debug manual__2025-03-03T12:50:23.237075+00:00 [queued]>
[2025-03-03T12:54:51.141+0000] {taskinstance.py:1157} INFO - Dependencies all met for dep_context=requeueable deps ti=<TaskInstance: xkcd_dbt_transformations.dbt_debug manual__2025-03-03T12:50:23.237075+00:00 [queued]>
[2025-03-03T12:54:51.141+0000] {taskinstance.py:1359} INFO - Starting attempt 2 of 3
[2025-03-03T12:54:51.147+0000] {taskinstance.py:1380} INFO - Executing <Task(BashOperator): dbt_debug> on 2025-03-03 12:50:23.237075+00:00
[2025-03-03T12:54:51.150+0000] {standard_task_runner.py:57} INFO - Started process 354 to run task
[2025-03-03T12:54:51.152+0000] {standard_task_runner.py:84} INFO - Running: ['***', 'tasks', 'run', 'xkcd_dbt_transformations', 'dbt_debug', 'manual__2025-03-03T12:50:23.237075+00:00', '--job-id', '99', '--raw', '--subdir', 'DAGS_FOLDER/xkcd_dbt_transformations.py', '--cfg-path', '/tmp/tmpa8p6693a']
[2025-03-03T12:54:51.154+0000] {standard_task_runner.py:85} INFO - Job 99: Subtask dbt_debug
[2025-03-03T12:54:51.176+0000] {task_command.py:415} INFO - Running <TaskInstance: xkcd_dbt_transformations.dbt_debug manual__2025-03-03T12:50:23.237075+00:00 [running]> on host e42a692d6092
[2025-03-03T12:54:51.212+0000] {taskinstance.py:1660} INFO - Exporting env vars: AIRFLOW_CTX_DAG_OWNER='***' AIRFLOW_CTX_DAG_ID='xkcd_dbt_transformations' AIRFLOW_CTX_TASK_ID='dbt_debug' AIRFLOW_CTX_EXECUTION_DATE='2025-03-03T12:50:23.237075+00:00' AIRFLOW_CTX_TRY_NUMBER='2' AIRFLOW_CTX_DAG_RUN_ID='manual__2025-03-03T12:50:23.237075+00:00'
[2025-03-03T12:54:51.212+0000] {subprocess.py:63} INFO - Tmp dir root location: /tmp
[2025-03-03T12:54:51.213+0000] {subprocess.py:75} INFO - Running command: ['/bin/bash', '-c', 'cd /opt/dbt && /home/***/.local/bin/dbt debug --no-use-colors']
[2025-03-03T12:54:51.217+0000] {subprocess.py:86} INFO - Output:
[2025-03-03T12:54:52.884+0000] {subprocess.py:93} INFO - 12:54:52  Sending event: {'category': 'dbt', 'action': 'invocation', 'label': 'start', 'context': [<snowplow_tracker.self_describing_json.SelfDescribingJson object at 0xffffb4220df0>, <snowplow_tracker.self_describing_json.SelfDescribingJson object at 0xffffb1f7bc70>, <snowplow_tracker.self_describing_json.SelfDescribingJson object at 0xffffb1f7b820>]}
[2025-03-03T12:54:52.885+0000] {subprocess.py:93} INFO - 12:54:52  Running with dbt=1.7.18
[2025-03-03T12:54:52.885+0000] {subprocess.py:93} INFO - 12:54:52  running dbt with arguments {'printer_width': '80', 'indirect_selection': 'eager', 'log_cache_events': 'False', 'write_json': 'True', 'partial_parse': 'True', 'cache_selected_only': 'False', 'profiles_dir': '/opt/dbt', 'fail_fast': 'False', 'version_check': 'True', 'log_path': '/opt/dbt/logs', 'debug': 'True', 'warn_error': 'None', 'use_colors': 'False', 'use_experimental_parser': 'False', 'no_print': 'None', 'quiet': 'False', 'log_format': 'default', 'static_parser': 'True', 'introspect': 'True', 'warn_error_options': 'WarnErrorOptions(include=[], exclude=[])', 'target_path': 'None', 'invocation_command': 'dbt debug --no-use-colors', 'send_anonymous_usage_stats': 'True'}
[2025-03-03T12:54:52.885+0000] {subprocess.py:93} INFO - 12:54:52  dbt version: 1.7.18
[2025-03-03T12:54:52.886+0000] {subprocess.py:93} INFO - 12:54:52  python version: 3.9.18
[2025-03-03T12:54:52.886+0000] {subprocess.py:93} INFO - 12:54:52  python path: /usr/local/bin/python
[2025-03-03T12:54:52.886+0000] {subprocess.py:93} INFO - 12:54:52  os info: Linux-6.10.14-linuxkit-aarch64-with-glibc2.31
[2025-03-03T12:54:52.950+0000] {subprocess.py:93} INFO - 12:54:52  Using profiles dir at /opt/dbt
[2025-03-03T12:54:52.951+0000] {subprocess.py:93} INFO - 12:54:52  Using profiles.yml file at /opt/dbt/profiles.yml
[2025-03-03T12:54:52.951+0000] {subprocess.py:93} INFO - 12:54:52  Using dbt_project.yml file at /opt/dbt/dbt_project.yml
[2025-03-03T12:54:52.952+0000] {subprocess.py:93} INFO - 12:54:52  adapter type: postgres
[2025-03-03T12:54:52.952+0000] {subprocess.py:93} INFO - 12:54:52  adapter version: 1.7.18
[2025-03-03T12:54:52.955+0000] {subprocess.py:93} INFO - 12:54:52  Encountered an error:
[2025-03-03T12:54:52.955+0000] {subprocess.py:93} INFO - 'bool' object is not iterable
[2025-03-03T12:54:52.958+0000] {subprocess.py:93} INFO - 12:54:52  Traceback (most recent call last):
[2025-03-03T12:54:52.958+0000] {subprocess.py:93} INFO -   File "/home/***/.local/lib/python3.9/site-packages/dbt/cli/requires.py", line 91, in wrapper
[2025-03-03T12:54:52.958+0000] {subprocess.py:93} INFO -     result, success = func(*args, **kwargs)
[2025-03-03T12:54:52.959+0000] {subprocess.py:93} INFO -   File "/home/***/.local/lib/python3.9/site-packages/dbt/cli/requires.py", line 76, in wrapper
[2025-03-03T12:54:52.959+0000] {subprocess.py:93} INFO -     return func(*args, **kwargs)
[2025-03-03T12:54:52.959+0000] {subprocess.py:93} INFO -   File "/home/***/.local/lib/python3.9/site-packages/dbt/cli/main.py", line 445, in debug
[2025-03-03T12:54:52.959+0000] {subprocess.py:93} INFO -     results = task.run()
[2025-03-03T12:54:52.959+0000] {subprocess.py:93} INFO -   File "/home/***/.local/lib/python3.9/site-packages/dbt/task/debug.py", line 142, in run
[2025-03-03T12:54:52.959+0000] {subprocess.py:93} INFO -     load_project_status: SubtaskStatus = self._load_project()
[2025-03-03T12:54:52.959+0000] {subprocess.py:93} INFO -   File "/home/***/.local/lib/python3.9/site-packages/dbt/task/debug.py", line 343, in _load_project
[2025-03-03T12:54:52.959+0000] {subprocess.py:93} INFO -     self.project = Project.from_project_root(
[2025-03-03T12:54:52.960+0000] {subprocess.py:93} INFO -   File "/home/***/.local/lib/python3.9/site-packages/dbt/config/project.py", line 753, in from_project_root
[2025-03-03T12:54:52.960+0000] {subprocess.py:93} INFO -     return partial.render(renderer)
[2025-03-03T12:54:52.960+0000] {subprocess.py:93} INFO -   File "/home/***/.local/lib/python3.9/site-packages/dbt/config/project.py", line 336, in render
[2025-03-03T12:54:52.960+0000] {subprocess.py:93} INFO -     return self.create_project(rendered)
[2025-03-03T12:54:52.960+0000] {subprocess.py:93} INFO -   File "/home/***/.local/lib/python3.9/site-packages/dbt/config/project.py", line 377, in create_project
[2025-03-03T12:54:52.960+0000] {subprocess.py:93} INFO -     dbt_version = _get_required_version(
[2025-03-03T12:54:52.960+0000] {subprocess.py:93} INFO -   File "/home/***/.local/lib/python3.9/site-packages/dbt/config/project.py", line 265, in _get_required_version
[2025-03-03T12:54:52.960+0000] {subprocess.py:93} INFO -     dbt_version = _parse_versions(dbt_raw_version)
[2025-03-03T12:54:52.960+0000] {subprocess.py:93} INFO -   File "/home/***/.local/lib/python3.9/site-packages/dbt/config/project.py", line 168, in _parse_versions
[2025-03-03T12:54:52.961+0000] {subprocess.py:93} INFO -     return [VersionSpecifier.from_version_string(v) for v in versions]
[2025-03-03T12:54:52.961+0000] {subprocess.py:93} INFO - TypeError: 'bool' object is not iterable
[2025-03-03T12:54:52.961+0000] {subprocess.py:93} INFO - 
[2025-03-03T12:54:52.961+0000] {subprocess.py:93} INFO - 12:54:52  Resource report: {"command_name": "debug", "command_wall_clock_time": 0.11127983, "process_user_time": 1.654284, "process_kernel_time": 0.067956, "process_mem_max_rss": "155808", "process_in_blocks": "168", "process_out_blocks": "2535", "command_success": false}
[2025-03-03T12:54:52.961+0000] {subprocess.py:93} INFO - 12:54:52  Command `dbt debug` failed at 12:54:52.959556 after 0.11 seconds
[2025-03-03T12:54:52.961+0000] {subprocess.py:93} INFO - 12:54:52  Sending event: {'category': 'dbt', 'action': 'invocation', 'label': 'end', 'context': [<snowplow_tracker.self_describing_json.SelfDescribingJson object at 0xffffb4220df0>, <snowplow_tracker.self_describing_json.SelfDescribingJson object at 0xffffb1e2b430>, <snowplow_tracker.self_describing_json.SelfDescribingJson object at 0xffffb1e2b520>]}
[2025-03-03T12:54:52.961+0000] {subprocess.py:93} INFO - 12:54:52  Flushing usage events
[2025-03-03T12:54:53.749+0000] {subprocess.py:97} INFO - Command exited with return code 2
[2025-03-03T12:54:53.754+0000] {taskinstance.py:1935} ERROR - Task failed with exception
Traceback (most recent call last):
  File "/home/airflow/.local/lib/python3.9/site-packages/airflow/operators/bash.py", line 210, in execute
    raise AirflowException(
airflow.exceptions.AirflowException: Bash command failed. The command returned a non-zero exit code 2.
[2025-03-03T12:54:53.756+0000] {taskinstance.py:1398} INFO - Marking task as UP_FOR_RETRY. dag_id=xkcd_dbt_transformations, task_id=dbt_debug, execution_date=20250303T125023, start_date=20250303T125451, end_date=20250303T125453
[2025-03-03T12:54:53.762+0000] {standard_task_runner.py:104} ERROR - Failed to execute job 99 for task dbt_debug (Bash command failed. The command returned a non-zero exit code 2.; 354)
[2025-03-03T12:54:53.774+0000] {local_task_job_runner.py:228} INFO - Task exited with return code 1
[2025-03-03T12:54:53.784+0000] {taskinstance.py:2776} INFO - 0 downstream tasks scheduled from follow-on schedule check
