[2025-03-03T12:57:11.662+0000] {taskinstance.py:1157} INFO - Dependencies all met for dep_context=non-requeueable deps ti=<TaskInstance: xkcd_dbt_transformations.dbt_debug manual__2025-03-03T12:50:23.237075+00:00 [queued]>
[2025-03-03T12:57:11.666+0000] {taskinstance.py:1157} INFO - Dependencies all met for dep_context=requeueable deps ti=<TaskInstance: xkcd_dbt_transformations.dbt_debug manual__2025-03-03T12:50:23.237075+00:00 [queued]>
[2025-03-03T12:57:11.666+0000] {taskinstance.py:1359} INFO - Starting attempt 3 of 4
[2025-03-03T12:57:11.670+0000] {taskinstance.py:1380} INFO - Executing <Task(BashOperator): dbt_debug> on 2025-03-03 12:50:23.237075+00:00
[2025-03-03T12:57:11.673+0000] {standard_task_runner.py:57} INFO - Started process 405 to run task
[2025-03-03T12:57:11.674+0000] {standard_task_runner.py:84} INFO - Running: ['***', 'tasks', 'run', 'xkcd_dbt_transformations', 'dbt_debug', 'manual__2025-03-03T12:50:23.237075+00:00', '--job-id', '101', '--raw', '--subdir', 'DAGS_FOLDER/xkcd_dbt_transformations.py', '--cfg-path', '/tmp/tmpv65cjby4']
[2025-03-03T12:57:11.675+0000] {standard_task_runner.py:85} INFO - Job 101: Subtask dbt_debug
[2025-03-03T12:57:11.693+0000] {task_command.py:415} INFO - Running <TaskInstance: xkcd_dbt_transformations.dbt_debug manual__2025-03-03T12:50:23.237075+00:00 [running]> on host e42a692d6092
[2025-03-03T12:57:11.719+0000] {taskinstance.py:1660} INFO - Exporting env vars: AIRFLOW_CTX_DAG_OWNER='***' AIRFLOW_CTX_DAG_ID='xkcd_dbt_transformations' AIRFLOW_CTX_TASK_ID='dbt_debug' AIRFLOW_CTX_EXECUTION_DATE='2025-03-03T12:50:23.237075+00:00' AIRFLOW_CTX_TRY_NUMBER='3' AIRFLOW_CTX_DAG_RUN_ID='manual__2025-03-03T12:50:23.237075+00:00'
[2025-03-03T12:57:11.720+0000] {subprocess.py:63} INFO - Tmp dir root location: /tmp
[2025-03-03T12:57:11.720+0000] {subprocess.py:75} INFO - Running command: ['/bin/bash', '-c', 'cd /opt/dbt && /home/***/.local/bin/dbt debug --no-use-colors']
[2025-03-03T12:57:11.724+0000] {subprocess.py:86} INFO - Output:
[2025-03-03T12:57:13.144+0000] {subprocess.py:93} INFO - 12:57:13  Sending event: {'category': 'dbt', 'action': 'invocation', 'label': 'start', 'context': [<snowplow_tracker.self_describing_json.SelfDescribingJson object at 0xffff805c0670>, <snowplow_tracker.self_describing_json.SelfDescribingJson object at 0xffff7e4a9fd0>, <snowplow_tracker.self_describing_json.SelfDescribingJson object at 0xffff7e4a95b0>]}
[2025-03-03T12:57:13.144+0000] {subprocess.py:93} INFO - 12:57:13  Running with dbt=1.7.18
[2025-03-03T12:57:13.145+0000] {subprocess.py:93} INFO - 12:57:13  running dbt with arguments {'printer_width': '80', 'indirect_selection': 'eager', 'log_cache_events': 'False', 'write_json': 'True', 'partial_parse': 'True', 'cache_selected_only': 'False', 'warn_error': 'None', 'debug': 'True', 'version_check': 'True', 'log_path': '/opt/dbt/logs', 'profiles_dir': '/opt/dbt', 'fail_fast': 'False', 'use_colors': 'False', 'use_experimental_parser': 'False', 'no_print': 'None', 'quiet': 'False', 'log_format': 'default', 'static_parser': 'True', 'invocation_command': 'dbt debug --no-use-colors', 'introspect': 'True', 'target_path': 'None', 'warn_error_options': 'WarnErrorOptions(include=[], exclude=[])', 'send_anonymous_usage_stats': 'True'}
[2025-03-03T12:57:13.145+0000] {subprocess.py:93} INFO - 12:57:13  dbt version: 1.7.18
[2025-03-03T12:57:13.145+0000] {subprocess.py:93} INFO - 12:57:13  python version: 3.9.18
[2025-03-03T12:57:13.146+0000] {subprocess.py:93} INFO - 12:57:13  python path: /usr/local/bin/python
[2025-03-03T12:57:13.146+0000] {subprocess.py:93} INFO - 12:57:13  os info: Linux-6.10.14-linuxkit-aarch64-with-glibc2.31
[2025-03-03T12:57:13.204+0000] {subprocess.py:93} INFO - 12:57:13  Using profiles dir at /opt/dbt
[2025-03-03T12:57:13.204+0000] {subprocess.py:93} INFO - 12:57:13  Using profiles.yml file at /opt/dbt/profiles.yml
[2025-03-03T12:57:13.204+0000] {subprocess.py:93} INFO - 12:57:13  Using dbt_project.yml file at /opt/dbt/dbt_project.yml
[2025-03-03T12:57:13.205+0000] {subprocess.py:93} INFO - 12:57:13  adapter type: postgres
[2025-03-03T12:57:13.205+0000] {subprocess.py:93} INFO - 12:57:13  adapter version: 1.7.18
[2025-03-03T12:57:13.247+0000] {subprocess.py:93} INFO - 12:57:13  Configuration:
[2025-03-03T12:57:13.248+0000] {subprocess.py:93} INFO - 12:57:13    profiles.yml file [OK found and valid]
[2025-03-03T12:57:13.248+0000] {subprocess.py:93} INFO - 12:57:13    dbt_project.yml file [OK found and valid]
[2025-03-03T12:57:13.249+0000] {subprocess.py:93} INFO - 12:57:13  Required dependencies:
[2025-03-03T12:57:13.249+0000] {subprocess.py:93} INFO - 12:57:13  Executing "git --help"
[2025-03-03T12:57:13.251+0000] {subprocess.py:93} INFO - 12:57:13   - git [ERROR]
[2025-03-03T12:57:13.252+0000] {subprocess.py:93} INFO - 
[2025-03-03T12:57:13.252+0000] {subprocess.py:93} INFO - 12:57:13  Connection:
[2025-03-03T12:57:13.252+0000] {subprocess.py:93} INFO - 12:57:13    host: postgres
[2025-03-03T12:57:13.253+0000] {subprocess.py:93} INFO - 12:57:13    port: 5432
[2025-03-03T12:57:13.253+0000] {subprocess.py:93} INFO - 12:57:13    user: ***
[2025-03-03T12:57:13.253+0000] {subprocess.py:93} INFO - 12:57:13    database: xkcd
[2025-03-03T12:57:13.254+0000] {subprocess.py:93} INFO - 12:57:13    schema: public
[2025-03-03T12:57:13.254+0000] {subprocess.py:93} INFO - 12:57:13    connect_timeout: 10
[2025-03-03T12:57:13.254+0000] {subprocess.py:93} INFO - 12:57:13    role: None
[2025-03-03T12:57:13.255+0000] {subprocess.py:93} INFO - 12:57:13    search_path: None
[2025-03-03T12:57:13.255+0000] {subprocess.py:93} INFO - 12:57:13    keepalives_idle: 0
[2025-03-03T12:57:13.255+0000] {subprocess.py:93} INFO - 12:57:13    sslmode: None
[2025-03-03T12:57:13.256+0000] {subprocess.py:93} INFO - 12:57:13    sslcert: None
[2025-03-03T12:57:13.256+0000] {subprocess.py:93} INFO - 12:57:13    sslkey: None
[2025-03-03T12:57:13.256+0000] {subprocess.py:93} INFO - 12:57:13    sslrootcert: None
[2025-03-03T12:57:13.256+0000] {subprocess.py:93} INFO - 12:57:13    application_name: dbt
[2025-03-03T12:57:13.257+0000] {subprocess.py:93} INFO - 12:57:13    retries: 1
[2025-03-03T12:57:13.257+0000] {subprocess.py:93} INFO - 12:57:13  Registered adapter: postgres=1.7.18
[2025-03-03T12:57:13.257+0000] {subprocess.py:93} INFO - 12:57:13  Acquiring new postgres connection 'debug'
[2025-03-03T12:57:13.258+0000] {subprocess.py:93} INFO - 12:57:13  Using postgres connection "debug"
[2025-03-03T12:57:13.258+0000] {subprocess.py:93} INFO - 12:57:13  On debug: select 1 as id
[2025-03-03T12:57:13.258+0000] {subprocess.py:93} INFO - 12:57:13  Opening a new connection, currently in state init
[2025-03-03T12:57:13.261+0000] {subprocess.py:93} INFO - 12:57:13  SQL status: SELECT 1 in 0.0 seconds
[2025-03-03T12:57:13.262+0000] {subprocess.py:93} INFO - 12:57:13  On debug: Close
[2025-03-03T12:57:13.262+0000] {subprocess.py:93} INFO - 12:57:13    Connection test: [OK connection ok]
[2025-03-03T12:57:13.262+0000] {subprocess.py:93} INFO - 
[2025-03-03T12:57:13.263+0000] {subprocess.py:93} INFO - 12:57:13  1 check failed:
[2025-03-03T12:57:13.263+0000] {subprocess.py:93} INFO - 12:57:13  Error from git --help: Could not find command, ensure it is in the user's PATH: "git"
[2025-03-03T12:57:13.263+0000] {subprocess.py:93} INFO - 
[2025-03-03T12:57:13.264+0000] {subprocess.py:93} INFO - 12:57:13  Resource report: {"command_name": "debug", "command_wall_clock_time": 0.14848788, "process_user_time": 1.477479, "process_kernel_time": 0.049115, "process_mem_max_rss": "155768", "process_out_blocks": "8", "command_success": false, "process_in_blocks": "0"}
[2025-03-03T12:57:13.264+0000] {subprocess.py:93} INFO - 12:57:13  Command `dbt debug` failed at 12:57:13.264439 after 0.15 seconds
[2025-03-03T12:57:13.264+0000] {subprocess.py:93} INFO - 12:57:13  Connection 'debug' was properly closed.
[2025-03-03T12:57:13.265+0000] {subprocess.py:93} INFO - 12:57:13  Sending event: {'category': 'dbt', 'action': 'invocation', 'label': 'end', 'context': [<snowplow_tracker.self_describing_json.SelfDescribingJson object at 0xffff805c0670>, <snowplow_tracker.self_describing_json.SelfDescribingJson object at 0xffff7e43ea00>, <snowplow_tracker.self_describing_json.SelfDescribingJson object at 0xffff7d9babb0>]}
[2025-03-03T12:57:13.265+0000] {subprocess.py:93} INFO - 12:57:13  Flushing usage events
[2025-03-03T12:57:14.065+0000] {subprocess.py:97} INFO - Command exited with return code 1
[2025-03-03T12:57:14.072+0000] {taskinstance.py:1935} ERROR - Task failed with exception
Traceback (most recent call last):
  File "/home/airflow/.local/lib/python3.9/site-packages/airflow/operators/bash.py", line 210, in execute
    raise AirflowException(
airflow.exceptions.AirflowException: Bash command failed. The command returned a non-zero exit code 1.
[2025-03-03T12:57:14.074+0000] {taskinstance.py:1398} INFO - Marking task as UP_FOR_RETRY. dag_id=xkcd_dbt_transformations, task_id=dbt_debug, execution_date=20250303T125023, start_date=20250303T125711, end_date=20250303T125714
[2025-03-03T12:57:14.080+0000] {standard_task_runner.py:104} ERROR - Failed to execute job 101 for task dbt_debug (Bash command failed. The command returned a non-zero exit code 1.; 405)
[2025-03-03T12:57:14.123+0000] {local_task_job_runner.py:228} INFO - Task exited with return code 1
[2025-03-03T12:57:14.136+0000] {taskinstance.py:2776} INFO - 0 downstream tasks scheduled from follow-on schedule check
