[2025-02-22T02:10:42.362+0000] {taskinstance.py:1157} INFO - Dependencies all met for dep_context=non-requeueable deps ti=<TaskInstance: xkcd_comics_ingestion.load_comics scheduled__2025-02-19T10:00:00+00:00 [queued]>
[2025-02-22T02:10:42.365+0000] {taskinstance.py:1157} INFO - Dependencies all met for dep_context=requeueable deps ti=<TaskInstance: xkcd_comics_ingestion.load_comics scheduled__2025-02-19T10:00:00+00:00 [queued]>
[2025-02-22T02:10:42.365+0000] {taskinstance.py:1359} INFO - Starting attempt 6 of 8
[2025-02-22T02:10:42.370+0000] {taskinstance.py:1380} INFO - Executing <Task(PythonOperator): load_comics> on 2025-02-19 10:00:00+00:00
[2025-02-22T02:10:42.372+0000] {standard_task_runner.py:57} INFO - Started process 21675 to run task
[2025-02-22T02:10:42.373+0000] {standard_task_runner.py:84} INFO - Running: ['***', 'tasks', 'run', 'xkcd_comics_ingestion', 'load_comics', 'scheduled__2025-02-19T10:00:00+00:00', '--job-id', '25', '--raw', '--subdir', 'DAGS_FOLDER/xkcd-comics-dag.py', '--cfg-path', '/tmp/tmph9lgjwdc']
[2025-02-22T02:10:42.374+0000] {standard_task_runner.py:85} INFO - Job 25: Subtask load_comics
[2025-02-22T02:10:42.392+0000] {task_command.py:415} INFO - Running <TaskInstance: xkcd_comics_ingestion.load_comics scheduled__2025-02-19T10:00:00+00:00 [running]> on host a231dcd502c3
[2025-02-22T02:10:42.419+0000] {taskinstance.py:1660} INFO - Exporting env vars: AIRFLOW_CTX_DAG_OWNER='***' AIRFLOW_CTX_DAG_ID='xkcd_comics_ingestion' AIRFLOW_CTX_TASK_ID='load_comics' AIRFLOW_CTX_EXECUTION_DATE='2025-02-19T10:00:00+00:00' AIRFLOW_CTX_TRY_NUMBER='6' AIRFLOW_CTX_DAG_RUN_ID='scheduled__2025-02-19T10:00:00+00:00'
[2025-02-22T02:10:42.901+0000] {xkcd-comics-dag.py:160} INFO - Performing historical load of all comics
[2025-02-22T02:10:43.018+0000] {taskinstance.py:1935} ERROR - Task failed with exception
Traceback (most recent call last):
  File "/home/airflow/.local/lib/python3.9/site-packages/airflow/operators/python.py", line 192, in execute
    return_value = self.execute_callable()
  File "/home/airflow/.local/lib/python3.9/site-packages/airflow/operators/python.py", line 209, in execute_callable
    return self.python_callable(*self.op_args, **self.op_kwargs)
  File "/opt/airflow/dags/xkcd-comics-dag.py", line 171, in load_comics
    if len(historical_comics) >= batch_size:
NameError: name 'batch_size' is not defined
[2025-02-22T02:10:43.025+0000] {taskinstance.py:1398} INFO - Marking task as UP_FOR_RETRY. dag_id=xkcd_comics_ingestion, task_id=load_comics, execution_date=20250219T100000, start_date=20250222T021042, end_date=20250222T021043
[2025-02-22T02:10:43.030+0000] {standard_task_runner.py:104} ERROR - Failed to execute job 25 for task load_comics (name 'batch_size' is not defined; 21675)
[2025-02-22T02:10:43.064+0000] {local_task_job_runner.py:228} INFO - Task exited with return code 1
[2025-02-22T02:10:43.073+0000] {taskinstance.py:2776} INFO - 0 downstream tasks scheduled from follow-on schedule check
