[2025-03-03T11:11:02.870+0000] {taskinstance.py:1157} INFO - Dependencies all met for dep_context=non-requeueable deps ti=<TaskInstance: xkcd_dbt_analytics.dbt_debug scheduled__2025-03-02T00:00:00+00:00 [queued]>
[2025-03-03T11:11:02.873+0000] {taskinstance.py:1157} INFO - Dependencies all met for dep_context=requeueable deps ti=<TaskInstance: xkcd_dbt_analytics.dbt_debug scheduled__2025-03-02T00:00:00+00:00 [queued]>
[2025-03-03T11:11:02.873+0000] {taskinstance.py:1359} INFO - Starting attempt 2 of 3
[2025-03-03T11:11:02.878+0000] {taskinstance.py:1380} INFO - Executing <Task(BashOperator): dbt_debug> on 2025-03-02 00:00:00+00:00
[2025-03-03T11:11:02.880+0000] {standard_task_runner.py:57} INFO - Started process 334 to run task
[2025-03-03T11:11:02.881+0000] {standard_task_runner.py:84} INFO - Running: ['***', 'tasks', 'run', 'xkcd_dbt_analytics', 'dbt_debug', 'scheduled__2025-03-02T00:00:00+00:00', '--job-id', '83', '--raw', '--subdir', 'DAGS_FOLDER/xkcd_dbt_dag.py', '--cfg-path', '/tmp/tmpozduic5k']
[2025-03-03T11:11:02.883+0000] {standard_task_runner.py:85} INFO - Job 83: Subtask dbt_debug
[2025-03-03T11:11:02.901+0000] {task_command.py:415} INFO - Running <TaskInstance: xkcd_dbt_analytics.dbt_debug scheduled__2025-03-02T00:00:00+00:00 [running]> on host 55c4a45e8eaa
[2025-03-03T11:11:02.930+0000] {taskinstance.py:1660} INFO - Exporting env vars: AIRFLOW_CTX_DAG_OWNER='***' AIRFLOW_CTX_DAG_ID='xkcd_dbt_analytics' AIRFLOW_CTX_TASK_ID='dbt_debug' AIRFLOW_CTX_EXECUTION_DATE='2025-03-02T00:00:00+00:00' AIRFLOW_CTX_TRY_NUMBER='2' AIRFLOW_CTX_DAG_RUN_ID='scheduled__2025-03-02T00:00:00+00:00'
[2025-03-03T11:11:02.930+0000] {subprocess.py:63} INFO - Tmp dir root location: /tmp
[2025-03-03T11:11:02.931+0000] {subprocess.py:75} INFO - Running command: ['/bin/bash', '-c', 'cd /opt/dbt && dbt debug']
[2025-03-03T11:11:02.934+0000] {subprocess.py:86} INFO - Output:
[2025-03-03T11:11:04.383+0000] {subprocess.py:93} INFO - [0m11:11:04  Running with dbt=1.7.18
[2025-03-03T11:11:04.384+0000] {subprocess.py:93} INFO - [0m11:11:04  dbt version: 1.7.18
[2025-03-03T11:11:04.385+0000] {subprocess.py:93} INFO - [0m11:11:04  python version: 3.9.18
[2025-03-03T11:11:04.385+0000] {subprocess.py:93} INFO - [0m11:11:04  python path: /usr/local/bin/python
[2025-03-03T11:11:04.386+0000] {subprocess.py:93} INFO - [0m11:11:04  os info: Linux-6.10.14-linuxkit-aarch64-with-glibc2.31
[2025-03-03T11:11:04.447+0000] {subprocess.py:93} INFO - [0m11:11:04  Using profiles dir at /opt/dbt
[2025-03-03T11:11:04.447+0000] {subprocess.py:93} INFO - [0m11:11:04  Using profiles.yml file at /opt/dbt/profiles.yml
[2025-03-03T11:11:04.448+0000] {subprocess.py:93} INFO - [0m11:11:04  Using dbt_project.yml file at /opt/dbt/dbt_project.yml
[2025-03-03T11:11:04.448+0000] {subprocess.py:93} INFO - [0m11:11:04  adapter type: postgres
[2025-03-03T11:11:04.449+0000] {subprocess.py:93} INFO - [0m11:11:04  adapter version: 1.7.18
[2025-03-03T11:11:04.488+0000] {subprocess.py:93} INFO - [0m11:11:04  Configuration:
[2025-03-03T11:11:04.489+0000] {subprocess.py:93} INFO - [0m11:11:04    profiles.yml file [[32mOK found and valid[0m]
[2025-03-03T11:11:04.489+0000] {subprocess.py:93} INFO - [0m11:11:04    dbt_project.yml file [[32mOK found and valid[0m]
[2025-03-03T11:11:04.490+0000] {subprocess.py:93} INFO - [0m11:11:04  Required dependencies:
[2025-03-03T11:11:04.492+0000] {subprocess.py:93} INFO - [0m11:11:04   - git [[31mERROR[0m]
[2025-03-03T11:11:04.492+0000] {subprocess.py:93} INFO - 
[2025-03-03T11:11:04.492+0000] {subprocess.py:93} INFO - [0m11:11:04  Connection:
[2025-03-03T11:11:04.493+0000] {subprocess.py:93} INFO - [0m11:11:04    host: postgres
[2025-03-03T11:11:04.493+0000] {subprocess.py:93} INFO - [0m11:11:04    port: 5432
[2025-03-03T11:11:04.494+0000] {subprocess.py:93} INFO - [0m11:11:04    user: ***
[2025-03-03T11:11:04.494+0000] {subprocess.py:93} INFO - [0m11:11:04    database: ***
[2025-03-03T11:11:04.494+0000] {subprocess.py:93} INFO - [0m11:11:04    schema: xkcd_dbt
[2025-03-03T11:11:04.495+0000] {subprocess.py:93} INFO - [0m11:11:04    connect_timeout: 10
[2025-03-03T11:11:04.495+0000] {subprocess.py:93} INFO - [0m11:11:04    role: None
[2025-03-03T11:11:04.495+0000] {subprocess.py:93} INFO - [0m11:11:04    search_path: None
[2025-03-03T11:11:04.496+0000] {subprocess.py:93} INFO - [0m11:11:04    keepalives_idle: 0
[2025-03-03T11:11:04.496+0000] {subprocess.py:93} INFO - [0m11:11:04    sslmode: None
[2025-03-03T11:11:04.496+0000] {subprocess.py:93} INFO - [0m11:11:04    sslcert: None
[2025-03-03T11:11:04.497+0000] {subprocess.py:93} INFO - [0m11:11:04    sslkey: None
[2025-03-03T11:11:04.497+0000] {subprocess.py:93} INFO - [0m11:11:04    sslrootcert: None
[2025-03-03T11:11:04.497+0000] {subprocess.py:93} INFO - [0m11:11:04    application_name: dbt
[2025-03-03T11:11:04.498+0000] {subprocess.py:93} INFO - [0m11:11:04    retries: 1
[2025-03-03T11:11:04.498+0000] {subprocess.py:93} INFO - [0m11:11:04  Registered adapter: postgres=1.7.18
[2025-03-03T11:11:04.504+0000] {subprocess.py:93} INFO - [0m11:11:04    Connection test: [[32mOK connection ok[0m]
[2025-03-03T11:11:04.504+0000] {subprocess.py:93} INFO - 
[2025-03-03T11:11:04.504+0000] {subprocess.py:93} INFO - [0m11:11:04  [31m1 check failed:[0m
[2025-03-03T11:11:04.505+0000] {subprocess.py:93} INFO - [0m11:11:04  Error from git --help: User does not have permissions for this command: "git"
[2025-03-03T11:11:04.505+0000] {subprocess.py:93} INFO - 
[2025-03-03T11:11:05.186+0000] {subprocess.py:97} INFO - Command exited with return code 1
[2025-03-03T11:11:05.191+0000] {taskinstance.py:1935} ERROR - Task failed with exception
Traceback (most recent call last):
  File "/home/airflow/.local/lib/python3.9/site-packages/airflow/operators/bash.py", line 210, in execute
    raise AirflowException(
airflow.exceptions.AirflowException: Bash command failed. The command returned a non-zero exit code 1.
[2025-03-03T11:11:05.193+0000] {taskinstance.py:1398} INFO - Marking task as UP_FOR_RETRY. dag_id=xkcd_dbt_analytics, task_id=dbt_debug, execution_date=20250302T000000, start_date=20250303T111102, end_date=20250303T111105
[2025-03-03T11:11:05.199+0000] {standard_task_runner.py:104} ERROR - Failed to execute job 83 for task dbt_debug (Bash command failed. The command returned a non-zero exit code 1.; 334)
[2025-03-03T11:11:05.220+0000] {local_task_job_runner.py:228} INFO - Task exited with return code 1
[2025-03-03T11:11:05.230+0000] {taskinstance.py:2776} INFO - 0 downstream tasks scheduled from follow-on schedule check
