[2025-02-22T10:14:45.633+0000] {taskinstance.py:1157} INFO - Dependencies all met for dep_context=non-requeueable deps ti=<TaskInstance: xkcd_comics_daily_load.load_comics_for_day scheduled__2020-01-10T00:00:00+00:00 [queued]>
[2025-02-22T10:14:45.637+0000] {taskinstance.py:1157} INFO - Dependencies all met for dep_context=requeueable deps ti=<TaskInstance: xkcd_comics_daily_load.load_comics_for_day scheduled__2020-01-10T00:00:00+00:00 [queued]>
[2025-02-22T10:14:45.637+0000] {taskinstance.py:1359} INFO - Starting attempt 1 of 4
[2025-02-22T10:14:45.642+0000] {taskinstance.py:1380} INFO - Executing <Task(PythonOperator): load_comics_for_day> on 2020-01-10 00:00:00+00:00
[2025-02-22T10:14:45.644+0000] {standard_task_runner.py:57} INFO - Started process 24040 to run task
[2025-02-22T10:14:45.646+0000] {standard_task_runner.py:84} INFO - Running: ['***', 'tasks', 'run', 'xkcd_comics_daily_load', 'load_comics_for_day', 'scheduled__2020-01-10T00:00:00+00:00', '--job-id', '46', '--raw', '--subdir', 'DAGS_FOLDER/xkcd-comics-dag.py', '--cfg-path', '/tmp/tmpa7ld707w']
[2025-02-22T10:14:45.647+0000] {standard_task_runner.py:85} INFO - Job 46: Subtask load_comics_for_day
[2025-02-22T10:14:45.665+0000] {task_command.py:415} INFO - Running <TaskInstance: xkcd_comics_daily_load.load_comics_for_day scheduled__2020-01-10T00:00:00+00:00 [running]> on host a231dcd502c3
[2025-02-22T10:14:45.695+0000] {taskinstance.py:1660} INFO - Exporting env vars: AIRFLOW_CTX_DAG_OWNER='***' AIRFLOW_CTX_DAG_ID='xkcd_comics_daily_load' AIRFLOW_CTX_TASK_ID='load_comics_for_day' AIRFLOW_CTX_EXECUTION_DATE='2020-01-10T00:00:00+00:00' AIRFLOW_CTX_TRY_NUMBER='1' AIRFLOW_CTX_DAG_RUN_ID='scheduled__2020-01-10T00:00:00+00:00'
[2025-02-22T10:14:46.093+0000] {logging_mixin.py:151} WARNING - /home/***/.local/lib/python3.9/site-packages/***/utils/context.py:314 AirflowContextDeprecationWarning: Accessing 'execution_date' from the template is deprecated and will be removed in a future version. Please use 'data_interval_start' or 'logical_date' instead.
[2025-02-22T10:15:36.279+0000] {xkcd-comics-dag.py:36} ERROR - Error fetching comic 404: 404 Client Error: Not Found for url: https://xkcd.com/404/info.0.json
[2025-02-22T10:30:36.325+0000] {xkcd-comics-dag.py:36} ERROR - Error fetching comic 2434: HTTPSConnectionPool(host='xkcd.com', port=443): Read timed out. (read timeout=10)
[2025-02-22T10:30:43.034+0000] {local_task_job_runner.py:294} WARNING - State of this instance has been externally set to up_for_retry. Terminating instance.
[2025-02-22T10:30:43.038+0000] {process_utils.py:131} INFO - Sending 15 to group 24040. PIDs of all processes in the group: [24040]
[2025-02-22T10:30:43.038+0000] {process_utils.py:86} INFO - Sending the signal 15 to group 24040
[2025-02-22T10:30:44.343+0000] {taskinstance.py:1630} ERROR - Received SIGTERM. Terminating subprocesses.
[2025-02-22T10:30:44.361+0000] {taskinstance.py:1935} ERROR - Task failed with exception
Traceback (most recent call last):
  File "/home/airflow/.local/lib/python3.9/site-packages/urllib3/connection.py", line 174, in _new_conn
    conn = connection.create_connection(
  File "/home/airflow/.local/lib/python3.9/site-packages/urllib3/util/connection.py", line 72, in create_connection
    for res in socket.getaddrinfo(host, port, family, socket.SOCK_STREAM):
  File "/usr/local/lib/python3.9/socket.py", line 954, in getaddrinfo
    for res in _socket.getaddrinfo(host, port, family, type, proto, flags):
socket.gaierror: [Errno -3] Temporary failure in name resolution

During handling of the above exception, another exception occurred:

Traceback (most recent call last):
  File "/home/airflow/.local/lib/python3.9/site-packages/airflow/operators/python.py", line 192, in execute
    return_value = self.execute_callable()
  File "/home/airflow/.local/lib/python3.9/site-packages/airflow/operators/python.py", line 209, in execute_callable
    return self.python_callable(*self.op_args, **self.op_kwargs)
  File "/opt/airflow/dags/xkcd-comics-dag.py", line 141, in load_comics_for_day
    comic = fetch_comic(comic_id)
  File "/opt/airflow/dags/xkcd-comics-dag.py", line 32, in fetch_comic
    response = requests.get(url, timeout=10)
  File "/home/airflow/.local/lib/python3.9/site-packages/requests/api.py", line 73, in get
    return request("get", url, params=params, **kwargs)
  File "/home/airflow/.local/lib/python3.9/site-packages/requests/api.py", line 59, in request
    return session.request(method=method, url=url, **kwargs)
  File "/home/airflow/.local/lib/python3.9/site-packages/requests/sessions.py", line 589, in request
    resp = self.send(prep, **send_kwargs)
  File "/home/airflow/.local/lib/python3.9/site-packages/requests/sessions.py", line 703, in send
    r = adapter.send(request, **kwargs)
  File "/home/airflow/.local/lib/python3.9/site-packages/requests/adapters.py", line 486, in send
    resp = conn.urlopen(
  File "/home/airflow/.local/lib/python3.9/site-packages/urllib3/connectionpool.py", line 714, in urlopen
    httplib_response = self._make_request(
  File "/home/airflow/.local/lib/python3.9/site-packages/urllib3/connectionpool.py", line 403, in _make_request
    self._validate_conn(conn)
  File "/home/airflow/.local/lib/python3.9/site-packages/urllib3/connectionpool.py", line 1053, in _validate_conn
    conn.connect()
  File "/home/airflow/.local/lib/python3.9/site-packages/urllib3/connection.py", line 363, in connect
    self.sock = conn = self._new_conn()
  File "/home/airflow/.local/lib/python3.9/site-packages/urllib3/connection.py", line 174, in _new_conn
    conn = connection.create_connection(
  File "/home/airflow/.local/lib/python3.9/site-packages/airflow/models/taskinstance.py", line 1632, in signal_handler
    raise AirflowException("Task received SIGTERM signal")
airflow.exceptions.AirflowException: Task received SIGTERM signal
[2025-02-22T10:30:44.369+0000] {taskinstance.py:1398} INFO - Marking task as UP_FOR_RETRY. dag_id=xkcd_comics_daily_load, task_id=load_comics_for_day, execution_date=20200110T000000, start_date=20250222T101445, end_date=20250222T103044
[2025-02-22T10:30:44.380+0000] {standard_task_runner.py:104} ERROR - Failed to execute job 46 for task load_comics_for_day (Task received SIGTERM signal; 24040)
[2025-02-22T10:30:44.422+0000] {process_utils.py:79} INFO - Process psutil.Process(pid=24040, status='terminated', exitcode=1, started='10:14:45') (24040) terminated with exit code 1
