[2025-02-17T19:23:52.548+0000] {taskinstance.py:1157} INFO - Dependencies all met for dep_context=non-requeueable deps ti=<TaskInstance: xkcd_comics.load_comics manual__2025-02-17T18:15:05.380214+00:00 [queued]>
[2025-02-17T19:23:52.552+0000] {taskinstance.py:1157} INFO - Dependencies all met for dep_context=requeueable deps ti=<TaskInstance: xkcd_comics.load_comics manual__2025-02-17T18:15:05.380214+00:00 [queued]>
[2025-02-17T19:23:52.553+0000] {taskinstance.py:1359} INFO - Starting attempt 5 of 7
[2025-02-17T19:23:52.558+0000] {taskinstance.py:1380} INFO - Executing <Task(PythonOperator): load_comics> on 2025-02-17 18:15:05.380214+00:00
[2025-02-17T19:23:52.561+0000] {standard_task_runner.py:57} INFO - Started process 1320 to run task
[2025-02-17T19:23:52.565+0000] {standard_task_runner.py:84} INFO - Running: ['***', 'tasks', 'run', 'xkcd_comics', 'load_comics', 'manual__2025-02-17T18:15:05.380214+00:00', '--job-id', '15', '--raw', '--subdir', 'DAGS_FOLDER/xkcd-comics-dag.py', '--cfg-path', '/tmp/tmp_4g1rb9f']
[2025-02-17T19:23:52.568+0000] {standard_task_runner.py:85} INFO - Job 15: Subtask load_comics
[2025-02-17T19:23:52.581+0000] {logging_mixin.py:151} WARNING - /home/***/.local/lib/python3.8/site-packages/***/settings.py:195 DeprecationWarning: The sql_alchemy_conn option in [core] has been moved to the sql_alchemy_conn option in [database] - the old setting has been used, but please update your config.
[2025-02-17T19:23:52.601+0000] {task_command.py:415} INFO - Running <TaskInstance: xkcd_comics.load_comics manual__2025-02-17T18:15:05.380214+00:00 [running]> on host ec6302870777
[2025-02-17T19:23:52.648+0000] {taskinstance.py:1660} INFO - Exporting env vars: AIRFLOW_CTX_DAG_OWNER='***' AIRFLOW_CTX_DAG_ID='xkcd_comics' AIRFLOW_CTX_TASK_ID='load_comics' AIRFLOW_CTX_EXECUTION_DATE='2025-02-17T18:15:05.380214+00:00' AIRFLOW_CTX_TRY_NUMBER='5' AIRFLOW_CTX_DAG_RUN_ID='manual__2025-02-17T18:15:05.380214+00:00'
[2025-02-17T19:23:52.728+0000] {logging_mixin.py:151} WARNING - --- Logging error ---
[2025-02-17T19:23:52.729+0000] {logging_mixin.py:151} WARNING - Traceback (most recent call last):
[2025-02-17T19:23:52.729+0000] {logging_mixin.py:151} WARNING -   File "/usr/local/lib/python3.8/logging/__init__.py", line 1085, in emit
    msg = self.format(record)
[2025-02-17T19:23:52.729+0000] {logging_mixin.py:151} WARNING -   File "/usr/local/lib/python3.8/logging/__init__.py", line 929, in format
    return fmt.format(record)
[2025-02-17T19:23:52.729+0000] {logging_mixin.py:151} WARNING -   File "/usr/local/lib/python3.8/logging/__init__.py", line 668, in format
    record.message = record.getMessage()
[2025-02-17T19:23:52.729+0000] {logging_mixin.py:151} WARNING -   File "/usr/local/lib/python3.8/logging/__init__.py", line 373, in getMessage
    msg = msg % self.args
[2025-02-17T19:23:52.730+0000] {logging_mixin.py:151} WARNING - TypeError: not all arguments converted during string formatting
[2025-02-17T19:23:52.730+0000] {logging_mixin.py:151} WARNING - Call stack:
[2025-02-17T19:23:52.731+0000] {logging_mixin.py:151} WARNING -   File "/home/***/.local/bin/***", line 8, in <module>
    sys.exit(main())
[2025-02-17T19:23:52.732+0000] {logging_mixin.py:151} WARNING -   File "/home/***/.local/lib/python3.8/site-packages/***/__main__.py", line 59, in main
    args.func(args)
[2025-02-17T19:23:52.732+0000] {logging_mixin.py:151} WARNING -   File "/home/***/.local/lib/python3.8/site-packages/***/cli/cli_config.py", line 49, in command
    return func(*args, **kwargs)
[2025-02-17T19:23:52.732+0000] {logging_mixin.py:151} WARNING -   File "/home/***/.local/lib/python3.8/site-packages/***/utils/cli.py", line 113, in wrapper
    return f(*args, **kwargs)
[2025-02-17T19:23:52.732+0000] {logging_mixin.py:151} WARNING -   File "/home/***/.local/lib/python3.8/site-packages/***/utils/providers_configuration_loader.py", line 55, in wrapped_function
    return func(*args, **kwargs)
[2025-02-17T19:23:52.732+0000] {logging_mixin.py:151} WARNING -   File "/home/***/.local/lib/python3.8/site-packages/***/cli/commands/scheduler_command.py", line 85, in scheduler
    _run_scheduler_job(job_runner, skip_serve_logs=args.skip_serve_logs)
[2025-02-17T19:23:52.732+0000] {logging_mixin.py:151} WARNING -   File "/home/***/.local/lib/python3.8/site-packages/***/cli/commands/scheduler_command.py", line 47, in _run_scheduler_job
    run_job(job=job_runner.job, execute_callable=job_runner._execute)
[2025-02-17T19:23:52.732+0000] {logging_mixin.py:151} WARNING -   File "/home/***/.local/lib/python3.8/site-packages/***/utils/session.py", line 77, in wrapper
    return func(*args, session=session, **kwargs)
[2025-02-17T19:23:52.733+0000] {logging_mixin.py:151} WARNING -   File "/home/***/.local/lib/python3.8/site-packages/***/jobs/job.py", line 289, in run_job
    return execute_job(job, execute_callable=execute_callable)
[2025-02-17T19:23:52.733+0000] {logging_mixin.py:151} WARNING -   File "/home/***/.local/lib/python3.8/site-packages/***/jobs/job.py", line 318, in execute_job
    ret = execute_callable()
[2025-02-17T19:23:52.733+0000] {logging_mixin.py:151} WARNING -   File "/home/***/.local/lib/python3.8/site-packages/***/jobs/scheduler_job_runner.py", line 836, in _execute
    self.job.executor.start()
[2025-02-17T19:23:52.733+0000] {logging_mixin.py:151} WARNING -   File "/home/***/.local/lib/python3.8/site-packages/***/executors/local_executor.py", line 371, in start
    self.impl.start()
[2025-02-17T19:23:52.733+0000] {logging_mixin.py:151} WARNING -   File "/home/***/.local/lib/python3.8/site-packages/***/executors/local_executor.py", line 308, in start
    worker.start()
[2025-02-17T19:23:52.733+0000] {logging_mixin.py:151} WARNING -   File "/usr/local/lib/python3.8/multiprocessing/process.py", line 121, in start
    self._popen = self._Popen(self)
[2025-02-17T19:23:52.733+0000] {logging_mixin.py:151} WARNING -   File "/usr/local/lib/python3.8/multiprocessing/context.py", line 224, in _Popen
    return _default_context.get_context().Process._Popen(process_obj)
[2025-02-17T19:23:52.733+0000] {logging_mixin.py:151} WARNING -   File "/usr/local/lib/python3.8/multiprocessing/context.py", line 277, in _Popen
    return Popen(process_obj)
[2025-02-17T19:23:52.734+0000] {logging_mixin.py:151} WARNING -   File "/usr/local/lib/python3.8/multiprocessing/popen_fork.py", line 19, in __init__
    self._launch(process_obj)
[2025-02-17T19:23:52.734+0000] {logging_mixin.py:151} WARNING -   File "/usr/local/lib/python3.8/multiprocessing/popen_fork.py", line 75, in _launch
    code = process_obj._bootstrap(parent_sentinel=child_r)
[2025-02-17T19:23:52.734+0000] {logging_mixin.py:151} WARNING -   File "/usr/local/lib/python3.8/multiprocessing/process.py", line 315, in _bootstrap
    self.run()
[2025-02-17T19:23:52.734+0000] {logging_mixin.py:151} WARNING -   File "/home/***/.local/lib/python3.8/site-packages/***/executors/local_executor.py", line 74, in run
    return super().run()
[2025-02-17T19:23:52.734+0000] {logging_mixin.py:151} WARNING -   File "/usr/local/lib/python3.8/multiprocessing/process.py", line 108, in run
    self._target(*self._args, **self._kwargs)
[2025-02-17T19:23:52.734+0000] {logging_mixin.py:151} WARNING -   File "/home/***/.local/lib/python3.8/site-packages/***/executors/local_executor.py", line 198, in do_work
    self.execute_work(key=key, command=command)
[2025-02-17T19:23:52.734+0000] {logging_mixin.py:151} WARNING -   File "/home/***/.local/lib/python3.8/site-packages/***/executors/local_executor.py", line 91, in execute_work
    state = self._execute_work_in_fork(command)
[2025-02-17T19:23:52.734+0000] {logging_mixin.py:151} WARNING -   File "/home/***/.local/lib/python3.8/site-packages/***/executors/local_executor.py", line 131, in _execute_work_in_fork
    args.func(args)
[2025-02-17T19:23:52.734+0000] {logging_mixin.py:151} WARNING -   File "/home/***/.local/lib/python3.8/site-packages/***/cli/cli_config.py", line 49, in command
    return func(*args, **kwargs)
[2025-02-17T19:23:52.734+0000] {logging_mixin.py:151} WARNING -   File "/home/***/.local/lib/python3.8/site-packages/***/utils/cli.py", line 113, in wrapper
    return f(*args, **kwargs)
[2025-02-17T19:23:52.735+0000] {logging_mixin.py:151} WARNING -   File "/home/***/.local/lib/python3.8/site-packages/***/cli/commands/task_command.py", line 430, in task_run
    task_return_code = _run_task_by_selected_method(args, _dag, ti)
[2025-02-17T19:23:52.735+0000] {logging_mixin.py:151} WARNING -   File "/home/***/.local/lib/python3.8/site-packages/***/cli/commands/task_command.py", line 208, in _run_task_by_selected_method
    return _run_task_by_local_task_job(args, ti)
[2025-02-17T19:23:52.735+0000] {logging_mixin.py:151} WARNING -   File "/home/***/.local/lib/python3.8/site-packages/***/cli/commands/task_command.py", line 270, in _run_task_by_local_task_job
    ret = run_job(job=job_runner.job, execute_callable=job_runner._execute)
[2025-02-17T19:23:52.735+0000] {logging_mixin.py:151} WARNING -   File "/home/***/.local/lib/python3.8/site-packages/***/utils/session.py", line 77, in wrapper
    return func(*args, session=session, **kwargs)
[2025-02-17T19:23:52.735+0000] {logging_mixin.py:151} WARNING -   File "/home/***/.local/lib/python3.8/site-packages/***/jobs/job.py", line 289, in run_job
    return execute_job(job, execute_callable=execute_callable)
[2025-02-17T19:23:52.735+0000] {logging_mixin.py:151} WARNING -   File "/home/***/.local/lib/python3.8/site-packages/***/jobs/job.py", line 318, in execute_job
    ret = execute_callable()
[2025-02-17T19:23:52.735+0000] {logging_mixin.py:151} WARNING -   File "/home/***/.local/lib/python3.8/site-packages/***/jobs/local_task_job_runner.py", line 159, in _execute
    self.task_runner.start()
[2025-02-17T19:23:52.735+0000] {logging_mixin.py:151} WARNING -   File "/home/***/.local/lib/python3.8/site-packages/***/task/task_runner/standard_task_runner.py", line 45, in start
    self.process = self._start_by_fork()
[2025-02-17T19:23:52.735+0000] {logging_mixin.py:151} WARNING -   File "/home/***/.local/lib/python3.8/site-packages/***/task/task_runner/standard_task_runner.py", line 97, in _start_by_fork
    ret = args.func(args, dag=self.dag)
[2025-02-17T19:23:52.736+0000] {logging_mixin.py:151} WARNING -   File "/home/***/.local/lib/python3.8/site-packages/***/cli/cli_config.py", line 49, in command
    return func(*args, **kwargs)
[2025-02-17T19:23:52.736+0000] {logging_mixin.py:151} WARNING -   File "/home/***/.local/lib/python3.8/site-packages/***/utils/cli.py", line 113, in wrapper
    return f(*args, **kwargs)
[2025-02-17T19:23:52.736+0000] {logging_mixin.py:151} WARNING -   File "/home/***/.local/lib/python3.8/site-packages/***/cli/commands/task_command.py", line 430, in task_run
    task_return_code = _run_task_by_selected_method(args, _dag, ti)
[2025-02-17T19:23:52.736+0000] {logging_mixin.py:151} WARNING -   File "/home/***/.local/lib/python3.8/site-packages/***/cli/commands/task_command.py", line 210, in _run_task_by_selected_method
    return _run_raw_task(args, ti)
[2025-02-17T19:23:52.736+0000] {logging_mixin.py:151} WARNING -   File "/home/***/.local/lib/python3.8/site-packages/***/cli/commands/task_command.py", line 289, in _run_raw_task
    return ti._run_raw_task(
[2025-02-17T19:23:52.736+0000] {logging_mixin.py:151} WARNING -   File "/home/***/.local/lib/python3.8/site-packages/***/utils/session.py", line 77, in wrapper
    return func(*args, session=session, **kwargs)
[2025-02-17T19:23:52.736+0000] {logging_mixin.py:151} WARNING -   File "/home/***/.local/lib/python3.8/site-packages/***/models/taskinstance.py", line 1516, in _run_raw_task
    self._execute_task_with_callbacks(context, test_mode, session=session)
[2025-02-17T19:23:52.736+0000] {logging_mixin.py:151} WARNING -   File "/home/***/.local/lib/python3.8/site-packages/***/models/taskinstance.py", line 1679, in _execute_task_with_callbacks
    result = self._execute_task(context, task_orig)
[2025-02-17T19:23:52.736+0000] {logging_mixin.py:151} WARNING -   File "/home/***/.local/lib/python3.8/site-packages/***/models/taskinstance.py", line 1742, in _execute_task
    result = execute_callable(context=context, **execute_callable_kwargs)
[2025-02-17T19:23:52.736+0000] {logging_mixin.py:151} WARNING -   File "/home/***/.local/lib/python3.8/site-packages/***/operators/python.py", line 192, in execute
    return_value = self.execute_callable()
[2025-02-17T19:23:52.736+0000] {logging_mixin.py:151} WARNING -   File "/home/***/.local/lib/python3.8/site-packages/***/operators/python.py", line 209, in execute_callable
    return self.python_callable(*self.op_args, **self.op_kwargs)
[2025-02-17T19:23:52.737+0000] {logging_mixin.py:151} WARNING -   File "/opt/***/dags/xkcd-comics-dag.py", line 122, in load_all_comics
    logging.info(latest_comic, 'latest_comic')
[2025-02-17T19:23:52.737+0000] {logging_mixin.py:151} WARNING -   File "/usr/local/lib/python3.8/logging/__init__.py", line 2082, in info
    root.info(msg, *args, **kwargs)
[2025-02-17T19:23:52.737+0000] {logging_mixin.py:151} WARNING -   File "/usr/local/lib/python3.8/logging/__init__.py", line 1446, in info
    self._log(INFO, msg, args, **kwargs)
[2025-02-17T19:23:52.737+0000] {logging_mixin.py:151} WARNING -   File "/usr/local/lib/python3.8/logging/__init__.py", line 1589, in _log
    self.handle(record)
[2025-02-17T19:23:52.737+0000] {logging_mixin.py:151} WARNING -   File "/usr/local/lib/python3.8/logging/__init__.py", line 1599, in handle
    self.callHandlers(record)
[2025-02-17T19:23:52.737+0000] {logging_mixin.py:151} WARNING -   File "/usr/local/lib/python3.8/logging/__init__.py", line 1661, in callHandlers
    hdlr.handle(record)
[2025-02-17T19:23:52.737+0000] {logging_mixin.py:151} WARNING -   File "/usr/local/lib/python3.8/logging/__init__.py", line 954, in handle
    self.emit(record)
[2025-02-17T19:23:52.737+0000] {logging_mixin.py:151} WARNING -   File "/home/***/.local/lib/python3.8/site-packages/***/utils/log/file_task_handler.py", line 211, in emit
    self.handler.emit(record)
[2025-02-17T19:23:52.737+0000] {logging_mixin.py:151} WARNING - Message: {'month': '2', 'num': 3051, 'link': '', 'year': '2025', 'news': '', 'safe_title': 'Hardwood', 'transcript': '', 'alt': "They may technically have been softwoods at some point, but they definitely aren't now.", 'img': 'https://imgs.xkcd.com/comics/hardwood.png', 'title': 'Hardwood', 'day': '14'}
Arguments: ('latest_comic',)
[2025-02-17T19:23:52.740+0000] {xkcd-comics-dag.py:130} INFO - Latest comic ID: 3051
[2025-02-17T19:23:52.740+0000] {xkcd-comics-dag.py:131} INFO - Latest stored comic ID: 3051
[2025-02-17T19:23:52.743+0000] {logging_mixin.py:151} INFO - Stored comic #3051: Hardwood
[2025-02-17T19:23:52.743+0000] {xkcd-comics-dag.py:141} INFO - Fetching comic #1
[2025-02-17T19:23:52.810+0000] {logging_mixin.py:151} INFO - Stored comic #1: Barrel - Part 1
[2025-02-17T19:23:53.818+0000] {xkcd-comics-dag.py:141} INFO - Fetching comic #2
[2025-02-17T19:23:53.893+0000] {logging_mixin.py:151} INFO - Stored comic #2: Petit Trees (sketch)
[2025-02-17T19:23:54.899+0000] {xkcd-comics-dag.py:141} INFO - Fetching comic #3
[2025-02-17T19:23:55.056+0000] {logging_mixin.py:151} INFO - Stored comic #3: Island (sketch)
[2025-02-17T19:23:56.065+0000] {xkcd-comics-dag.py:141} INFO - Fetching comic #4
[2025-02-17T19:23:56.410+0000] {logging_mixin.py:151} INFO - Stored comic #4: Landscape (sketch)
[2025-02-17T19:23:57.413+0000] {xkcd-comics-dag.py:141} INFO - Fetching comic #5
[2025-02-17T19:23:57.493+0000] {logging_mixin.py:151} INFO - Stored comic #5: Blown apart
[2025-02-17T19:23:58.498+0000] {xkcd-comics-dag.py:141} INFO - Fetching comic #6
[2025-02-17T19:23:58.581+0000] {logging_mixin.py:151} INFO - Stored comic #6: Irony
[2025-02-17T19:23:59.587+0000] {xkcd-comics-dag.py:141} INFO - Fetching comic #7
[2025-02-17T19:23:59.941+0000] {logging_mixin.py:151} INFO - Stored comic #7: Girl sleeping (Sketch -- 11th grade Spanish class)
[2025-02-17T19:24:00.944+0000] {xkcd-comics-dag.py:141} INFO - Fetching comic #8
[2025-02-17T19:24:01.026+0000] {logging_mixin.py:151} INFO - Stored comic #8: Red spiders
[2025-02-17T19:24:02.029+0000] {xkcd-comics-dag.py:141} INFO - Fetching comic #9
[2025-02-17T19:24:02.105+0000] {logging_mixin.py:151} INFO - Stored comic #9: Serenity is coming out tomorrow
[2025-02-17T19:24:03.112+0000] {xkcd-comics-dag.py:141} INFO - Fetching comic #10
[2025-02-17T19:24:03.456+0000] {logging_mixin.py:151} INFO - Stored comic #10: Pi Equals
[2025-02-17T19:24:04.460+0000] {xkcd-comics-dag.py:141} INFO - Fetching comic #11
[2025-02-17T19:24:04.812+0000] {logging_mixin.py:151} INFO - Stored comic #11: Barrel - Part 2
[2025-02-17T19:24:05.819+0000] {xkcd-comics-dag.py:141} INFO - Fetching comic #12
[2025-02-17T19:24:05.946+0000] {logging_mixin.py:151} INFO - Stored comic #12: Poisson
[2025-02-17T19:24:06.955+0000] {xkcd-comics-dag.py:141} INFO - Fetching comic #13
[2025-02-17T19:24:07.306+0000] {logging_mixin.py:151} INFO - Stored comic #13: Canyon
[2025-02-17T19:24:08.316+0000] {xkcd-comics-dag.py:141} INFO - Fetching comic #14
[2025-02-17T19:24:08.661+0000] {logging_mixin.py:151} INFO - Stored comic #14: Copyright
[2025-02-17T19:24:09.665+0000] {xkcd-comics-dag.py:141} INFO - Fetching comic #15
[2025-02-17T19:40:06.760+0000] {taskinstance.py:1935} ERROR - Task failed with exception
Traceback (most recent call last):
  File "/home/airflow/.local/lib/python3.8/site-packages/urllib3/connectionpool.py", line 714, in urlopen
    httplib_response = self._make_request(
  File "/home/airflow/.local/lib/python3.8/site-packages/urllib3/connectionpool.py", line 403, in _make_request
    self._validate_conn(conn)
  File "/home/airflow/.local/lib/python3.8/site-packages/urllib3/connectionpool.py", line 1053, in _validate_conn
    conn.connect()
  File "/home/airflow/.local/lib/python3.8/site-packages/urllib3/connection.py", line 419, in connect
    self.sock = ssl_wrap_socket(
  File "/home/airflow/.local/lib/python3.8/site-packages/urllib3/util/ssl_.py", line 449, in ssl_wrap_socket
    ssl_sock = _ssl_wrap_socket_impl(
  File "/home/airflow/.local/lib/python3.8/site-packages/urllib3/util/ssl_.py", line 493, in _ssl_wrap_socket_impl
    return ssl_context.wrap_socket(sock, server_hostname=server_hostname)
  File "/usr/local/lib/python3.8/ssl.py", line 500, in wrap_socket
    return self.sslsocket_class._create(
  File "/usr/local/lib/python3.8/ssl.py", line 1073, in _create
    self.do_handshake()
  File "/usr/local/lib/python3.8/ssl.py", line 1342, in do_handshake
    self._sslobj.do_handshake()
ssl.SSLEOFError: EOF occurred in violation of protocol (_ssl.c:1131)

During handling of the above exception, another exception occurred:

Traceback (most recent call last):
  File "/home/airflow/.local/lib/python3.8/site-packages/requests/adapters.py", line 486, in send
    resp = conn.urlopen(
  File "/home/airflow/.local/lib/python3.8/site-packages/urllib3/connectionpool.py", line 798, in urlopen
    retries = retries.increment(
  File "/home/airflow/.local/lib/python3.8/site-packages/urllib3/util/retry.py", line 592, in increment
    raise MaxRetryError(_pool, url, error or ResponseError(cause))
urllib3.exceptions.MaxRetryError: HTTPSConnectionPool(host='xkcd.com', port=443): Max retries exceeded with url: /15/info.0.json (Caused by SSLError(SSLEOFError(8, 'EOF occurred in violation of protocol (_ssl.c:1131)')))

During handling of the above exception, another exception occurred:

Traceback (most recent call last):
  File "/home/airflow/.local/lib/python3.8/site-packages/airflow/operators/python.py", line 192, in execute
    return_value = self.execute_callable()
  File "/home/airflow/.local/lib/python3.8/site-packages/airflow/operators/python.py", line 209, in execute_callable
    return self.python_callable(*self.op_args, **self.op_kwargs)
  File "/opt/airflow/dags/xkcd-comics-dag.py", line 142, in load_all_comics
    comic = fetch_comics(comic_id)
  File "/opt/airflow/dags/xkcd-comics-dag.py", line 69, in fetch_comics
    response = requests.get(url)
  File "/home/airflow/.local/lib/python3.8/site-packages/requests/api.py", line 73, in get
    return request("get", url, params=params, **kwargs)
  File "/home/airflow/.local/lib/python3.8/site-packages/requests/api.py", line 59, in request
    return session.request(method=method, url=url, **kwargs)
  File "/home/airflow/.local/lib/python3.8/site-packages/requests/sessions.py", line 589, in request
    resp = self.send(prep, **send_kwargs)
  File "/home/airflow/.local/lib/python3.8/site-packages/requests/sessions.py", line 703, in send
    r = adapter.send(request, **kwargs)
  File "/home/airflow/.local/lib/python3.8/site-packages/requests/adapters.py", line 517, in send
    raise SSLError(e, request=request)
requests.exceptions.SSLError: HTTPSConnectionPool(host='xkcd.com', port=443): Max retries exceeded with url: /15/info.0.json (Caused by SSLError(SSLEOFError(8, 'EOF occurred in violation of protocol (_ssl.c:1131)')))
[2025-02-17T19:40:06.769+0000] {taskinstance.py:1398} INFO - Marking task as UP_FOR_RETRY. dag_id=xkcd_comics, task_id=load_comics, execution_date=20250217T181505, start_date=20250217T192352, end_date=20250217T194006
[2025-02-17T19:40:06.774+0000] {standard_task_runner.py:104} ERROR - Failed to execute job 15 for task load_comics (HTTPSConnectionPool(host='xkcd.com', port=443): Max retries exceeded with url: /15/info.0.json (Caused by SSLError(SSLEOFError(8, 'EOF occurred in violation of protocol (_ssl.c:1131)'))); 1320)
[2025-02-17T19:40:06.826+0000] {local_task_job_runner.py:228} INFO - Task exited with return code 1
[2025-02-17T19:40:06.836+0000] {taskinstance.py:2776} INFO - 0 downstream tasks scheduled from follow-on schedule check
