[2025-02-17T18:01:06.954+0000] {taskinstance.py:1157} INFO - Dependencies all met for dep_context=non-requeueable deps ti=<TaskInstance: xkcd_comics.fetch_historical_comics manual__2025-02-17T18:01:05.214989+00:00 [queued]>
[2025-02-17T18:01:06.958+0000] {taskinstance.py:1157} INFO - Dependencies all met for dep_context=requeueable deps ti=<TaskInstance: xkcd_comics.fetch_historical_comics manual__2025-02-17T18:01:05.214989+00:00 [queued]>
[2025-02-17T18:01:06.958+0000] {taskinstance.py:1359} INFO - Starting attempt 1 of 4
[2025-02-17T18:01:06.963+0000] {taskinstance.py:1380} INFO - Executing <Task(PythonOperator): fetch_historical_comics> on 2025-02-17 18:01:05.214989+00:00
[2025-02-17T18:01:06.965+0000] {standard_task_runner.py:57} INFO - Started process 561 to run task
[2025-02-17T18:01:06.967+0000] {standard_task_runner.py:84} INFO - Running: ['***', 'tasks', 'run', 'xkcd_comics', 'fetch_historical_comics', 'manual__2025-02-17T18:01:05.214989+00:00', '--job-id', '5', '--raw', '--subdir', 'DAGS_FOLDER/xkcd-comics-dag.py', '--cfg-path', '/tmp/tmp79ec9_0d']
[2025-02-17T18:01:06.968+0000] {standard_task_runner.py:85} INFO - Job 5: Subtask fetch_historical_comics
[2025-02-17T18:01:06.976+0000] {logging_mixin.py:151} WARNING - /home/***/.local/lib/python3.8/site-packages/***/settings.py:195 DeprecationWarning: The sql_alchemy_conn option in [core] has been moved to the sql_alchemy_conn option in [database] - the old setting has been used, but please update your config.
[2025-02-17T18:01:06.989+0000] {task_command.py:415} INFO - Running <TaskInstance: xkcd_comics.fetch_historical_comics manual__2025-02-17T18:01:05.214989+00:00 [running]> on host ec6302870777
[2025-02-17T18:01:07.021+0000] {taskinstance.py:1660} INFO - Exporting env vars: AIRFLOW_CTX_DAG_OWNER='***' AIRFLOW_CTX_DAG_ID='xkcd_comics' AIRFLOW_CTX_TASK_ID='fetch_historical_comics' AIRFLOW_CTX_EXECUTION_DATE='2025-02-17T18:01:05.214989+00:00' AIRFLOW_CTX_TRY_NUMBER='1' AIRFLOW_CTX_DAG_RUN_ID='manual__2025-02-17T18:01:05.214989+00:00'
[2025-02-17T18:01:07.108+0000] {logging_mixin.py:151} WARNING - --- Logging error ---
[2025-02-17T18:01:07.109+0000] {logging_mixin.py:151} WARNING - Traceback (most recent call last):
[2025-02-17T18:01:07.109+0000] {logging_mixin.py:151} WARNING -   File "/usr/local/lib/python3.8/logging/__init__.py", line 1085, in emit
    msg = self.format(record)
[2025-02-17T18:01:07.109+0000] {logging_mixin.py:151} WARNING -   File "/usr/local/lib/python3.8/logging/__init__.py", line 929, in format
    return fmt.format(record)
[2025-02-17T18:01:07.109+0000] {logging_mixin.py:151} WARNING -   File "/usr/local/lib/python3.8/logging/__init__.py", line 668, in format
    record.message = record.getMessage()
[2025-02-17T18:01:07.109+0000] {logging_mixin.py:151} WARNING -   File "/usr/local/lib/python3.8/logging/__init__.py", line 373, in getMessage
    msg = msg % self.args
[2025-02-17T18:01:07.109+0000] {logging_mixin.py:151} WARNING - TypeError: not all arguments converted during string formatting
[2025-02-17T18:01:07.110+0000] {logging_mixin.py:151} WARNING - Call stack:
[2025-02-17T18:01:07.112+0000] {logging_mixin.py:151} WARNING -   File "/home/***/.local/bin/***", line 8, in <module>
    sys.exit(main())
[2025-02-17T18:01:07.112+0000] {logging_mixin.py:151} WARNING -   File "/home/***/.local/lib/python3.8/site-packages/***/__main__.py", line 59, in main
    args.func(args)
[2025-02-17T18:01:07.112+0000] {logging_mixin.py:151} WARNING -   File "/home/***/.local/lib/python3.8/site-packages/***/cli/cli_config.py", line 49, in command
    return func(*args, **kwargs)
[2025-02-17T18:01:07.113+0000] {logging_mixin.py:151} WARNING -   File "/home/***/.local/lib/python3.8/site-packages/***/utils/cli.py", line 113, in wrapper
    return f(*args, **kwargs)
[2025-02-17T18:01:07.113+0000] {logging_mixin.py:151} WARNING -   File "/home/***/.local/lib/python3.8/site-packages/***/utils/providers_configuration_loader.py", line 55, in wrapped_function
    return func(*args, **kwargs)
[2025-02-17T18:01:07.113+0000] {logging_mixin.py:151} WARNING -   File "/home/***/.local/lib/python3.8/site-packages/***/cli/commands/scheduler_command.py", line 85, in scheduler
    _run_scheduler_job(job_runner, skip_serve_logs=args.skip_serve_logs)
[2025-02-17T18:01:07.113+0000] {logging_mixin.py:151} WARNING -   File "/home/***/.local/lib/python3.8/site-packages/***/cli/commands/scheduler_command.py", line 47, in _run_scheduler_job
    run_job(job=job_runner.job, execute_callable=job_runner._execute)
[2025-02-17T18:01:07.114+0000] {logging_mixin.py:151} WARNING -   File "/home/***/.local/lib/python3.8/site-packages/***/utils/session.py", line 77, in wrapper
    return func(*args, session=session, **kwargs)
[2025-02-17T18:01:07.114+0000] {logging_mixin.py:151} WARNING -   File "/home/***/.local/lib/python3.8/site-packages/***/jobs/job.py", line 289, in run_job
    return execute_job(job, execute_callable=execute_callable)
[2025-02-17T18:01:07.114+0000] {logging_mixin.py:151} WARNING -   File "/home/***/.local/lib/python3.8/site-packages/***/jobs/job.py", line 318, in execute_job
    ret = execute_callable()
[2025-02-17T18:01:07.114+0000] {logging_mixin.py:151} WARNING -   File "/home/***/.local/lib/python3.8/site-packages/***/jobs/scheduler_job_runner.py", line 836, in _execute
    self.job.executor.start()
[2025-02-17T18:01:07.114+0000] {logging_mixin.py:151} WARNING -   File "/home/***/.local/lib/python3.8/site-packages/***/executors/local_executor.py", line 371, in start
    self.impl.start()
[2025-02-17T18:01:07.115+0000] {logging_mixin.py:151} WARNING -   File "/home/***/.local/lib/python3.8/site-packages/***/executors/local_executor.py", line 308, in start
    worker.start()
[2025-02-17T18:01:07.115+0000] {logging_mixin.py:151} WARNING -   File "/usr/local/lib/python3.8/multiprocessing/process.py", line 121, in start
    self._popen = self._Popen(self)
[2025-02-17T18:01:07.115+0000] {logging_mixin.py:151} WARNING -   File "/usr/local/lib/python3.8/multiprocessing/context.py", line 224, in _Popen
    return _default_context.get_context().Process._Popen(process_obj)
[2025-02-17T18:01:07.115+0000] {logging_mixin.py:151} WARNING -   File "/usr/local/lib/python3.8/multiprocessing/context.py", line 277, in _Popen
    return Popen(process_obj)
[2025-02-17T18:01:07.115+0000] {logging_mixin.py:151} WARNING -   File "/usr/local/lib/python3.8/multiprocessing/popen_fork.py", line 19, in __init__
    self._launch(process_obj)
[2025-02-17T18:01:07.115+0000] {logging_mixin.py:151} WARNING -   File "/usr/local/lib/python3.8/multiprocessing/popen_fork.py", line 75, in _launch
    code = process_obj._bootstrap(parent_sentinel=child_r)
[2025-02-17T18:01:07.115+0000] {logging_mixin.py:151} WARNING -   File "/usr/local/lib/python3.8/multiprocessing/process.py", line 315, in _bootstrap
    self.run()
[2025-02-17T18:01:07.115+0000] {logging_mixin.py:151} WARNING -   File "/home/***/.local/lib/python3.8/site-packages/***/executors/local_executor.py", line 74, in run
    return super().run()
[2025-02-17T18:01:07.116+0000] {logging_mixin.py:151} WARNING -   File "/usr/local/lib/python3.8/multiprocessing/process.py", line 108, in run
    self._target(*self._args, **self._kwargs)
[2025-02-17T18:01:07.116+0000] {logging_mixin.py:151} WARNING -   File "/home/***/.local/lib/python3.8/site-packages/***/executors/local_executor.py", line 198, in do_work
    self.execute_work(key=key, command=command)
[2025-02-17T18:01:07.116+0000] {logging_mixin.py:151} WARNING -   File "/home/***/.local/lib/python3.8/site-packages/***/executors/local_executor.py", line 91, in execute_work
    state = self._execute_work_in_fork(command)
[2025-02-17T18:01:07.116+0000] {logging_mixin.py:151} WARNING -   File "/home/***/.local/lib/python3.8/site-packages/***/executors/local_executor.py", line 131, in _execute_work_in_fork
    args.func(args)
[2025-02-17T18:01:07.116+0000] {logging_mixin.py:151} WARNING -   File "/home/***/.local/lib/python3.8/site-packages/***/cli/cli_config.py", line 49, in command
    return func(*args, **kwargs)
[2025-02-17T18:01:07.116+0000] {logging_mixin.py:151} WARNING -   File "/home/***/.local/lib/python3.8/site-packages/***/utils/cli.py", line 113, in wrapper
    return f(*args, **kwargs)
[2025-02-17T18:01:07.116+0000] {logging_mixin.py:151} WARNING -   File "/home/***/.local/lib/python3.8/site-packages/***/cli/commands/task_command.py", line 430, in task_run
    task_return_code = _run_task_by_selected_method(args, _dag, ti)
[2025-02-17T18:01:07.117+0000] {logging_mixin.py:151} WARNING -   File "/home/***/.local/lib/python3.8/site-packages/***/cli/commands/task_command.py", line 208, in _run_task_by_selected_method
    return _run_task_by_local_task_job(args, ti)
[2025-02-17T18:01:07.117+0000] {logging_mixin.py:151} WARNING -   File "/home/***/.local/lib/python3.8/site-packages/***/cli/commands/task_command.py", line 270, in _run_task_by_local_task_job
    ret = run_job(job=job_runner.job, execute_callable=job_runner._execute)
[2025-02-17T18:01:07.117+0000] {logging_mixin.py:151} WARNING -   File "/home/***/.local/lib/python3.8/site-packages/***/utils/session.py", line 77, in wrapper
    return func(*args, session=session, **kwargs)
[2025-02-17T18:01:07.117+0000] {logging_mixin.py:151} WARNING -   File "/home/***/.local/lib/python3.8/site-packages/***/jobs/job.py", line 289, in run_job
    return execute_job(job, execute_callable=execute_callable)
[2025-02-17T18:01:07.117+0000] {logging_mixin.py:151} WARNING -   File "/home/***/.local/lib/python3.8/site-packages/***/jobs/job.py", line 318, in execute_job
    ret = execute_callable()
[2025-02-17T18:01:07.117+0000] {logging_mixin.py:151} WARNING -   File "/home/***/.local/lib/python3.8/site-packages/***/jobs/local_task_job_runner.py", line 159, in _execute
    self.task_runner.start()
[2025-02-17T18:01:07.117+0000] {logging_mixin.py:151} WARNING -   File "/home/***/.local/lib/python3.8/site-packages/***/task/task_runner/standard_task_runner.py", line 45, in start
    self.process = self._start_by_fork()
[2025-02-17T18:01:07.117+0000] {logging_mixin.py:151} WARNING -   File "/home/***/.local/lib/python3.8/site-packages/***/task/task_runner/standard_task_runner.py", line 97, in _start_by_fork
    ret = args.func(args, dag=self.dag)
[2025-02-17T18:01:07.118+0000] {logging_mixin.py:151} WARNING -   File "/home/***/.local/lib/python3.8/site-packages/***/cli/cli_config.py", line 49, in command
    return func(*args, **kwargs)
[2025-02-17T18:01:07.118+0000] {logging_mixin.py:151} WARNING -   File "/home/***/.local/lib/python3.8/site-packages/***/utils/cli.py", line 113, in wrapper
    return f(*args, **kwargs)
[2025-02-17T18:01:07.118+0000] {logging_mixin.py:151} WARNING -   File "/home/***/.local/lib/python3.8/site-packages/***/cli/commands/task_command.py", line 430, in task_run
    task_return_code = _run_task_by_selected_method(args, _dag, ti)
[2025-02-17T18:01:07.118+0000] {logging_mixin.py:151} WARNING -   File "/home/***/.local/lib/python3.8/site-packages/***/cli/commands/task_command.py", line 210, in _run_task_by_selected_method
    return _run_raw_task(args, ti)
[2025-02-17T18:01:07.118+0000] {logging_mixin.py:151} WARNING -   File "/home/***/.local/lib/python3.8/site-packages/***/cli/commands/task_command.py", line 289, in _run_raw_task
    return ti._run_raw_task(
[2025-02-17T18:01:07.118+0000] {logging_mixin.py:151} WARNING -   File "/home/***/.local/lib/python3.8/site-packages/***/utils/session.py", line 77, in wrapper
    return func(*args, session=session, **kwargs)
[2025-02-17T18:01:07.118+0000] {logging_mixin.py:151} WARNING -   File "/home/***/.local/lib/python3.8/site-packages/***/models/taskinstance.py", line 1516, in _run_raw_task
    self._execute_task_with_callbacks(context, test_mode, session=session)
[2025-02-17T18:01:07.118+0000] {logging_mixin.py:151} WARNING -   File "/home/***/.local/lib/python3.8/site-packages/***/models/taskinstance.py", line 1679, in _execute_task_with_callbacks
    result = self._execute_task(context, task_orig)
[2025-02-17T18:01:07.119+0000] {logging_mixin.py:151} WARNING -   File "/home/***/.local/lib/python3.8/site-packages/***/models/taskinstance.py", line 1742, in _execute_task
    result = execute_callable(context=context, **execute_callable_kwargs)
[2025-02-17T18:01:07.119+0000] {logging_mixin.py:151} WARNING -   File "/home/***/.local/lib/python3.8/site-packages/***/operators/python.py", line 192, in execute
    return_value = self.execute_callable()
[2025-02-17T18:01:07.119+0000] {logging_mixin.py:151} WARNING -   File "/home/***/.local/lib/python3.8/site-packages/***/operators/python.py", line 209, in execute_callable
    return self.python_callable(*self.op_args, **self.op_kwargs)
[2025-02-17T18:01:07.119+0000] {logging_mixin.py:151} WARNING -   File "/opt/***/dags/xkcd-comics-dag.py", line 122, in fetch_all_comics
    logging.info(latest_comic, 'latest_comic')
[2025-02-17T18:01:07.119+0000] {logging_mixin.py:151} WARNING -   File "/usr/local/lib/python3.8/logging/__init__.py", line 2082, in info
    root.info(msg, *args, **kwargs)
[2025-02-17T18:01:07.119+0000] {logging_mixin.py:151} WARNING -   File "/usr/local/lib/python3.8/logging/__init__.py", line 1446, in info
    self._log(INFO, msg, args, **kwargs)
[2025-02-17T18:01:07.119+0000] {logging_mixin.py:151} WARNING -   File "/usr/local/lib/python3.8/logging/__init__.py", line 1589, in _log
    self.handle(record)
[2025-02-17T18:01:07.119+0000] {logging_mixin.py:151} WARNING -   File "/usr/local/lib/python3.8/logging/__init__.py", line 1599, in handle
    self.callHandlers(record)
[2025-02-17T18:01:07.120+0000] {logging_mixin.py:151} WARNING -   File "/usr/local/lib/python3.8/logging/__init__.py", line 1661, in callHandlers
    hdlr.handle(record)
[2025-02-17T18:01:07.120+0000] {logging_mixin.py:151} WARNING -   File "/usr/local/lib/python3.8/logging/__init__.py", line 954, in handle
    self.emit(record)
[2025-02-17T18:01:07.120+0000] {logging_mixin.py:151} WARNING -   File "/home/***/.local/lib/python3.8/site-packages/***/utils/log/file_task_handler.py", line 211, in emit
    self.handler.emit(record)
[2025-02-17T18:01:07.120+0000] {logging_mixin.py:151} WARNING - Message: {'month': '2', 'num': 3051, 'link': '', 'year': '2025', 'news': '', 'safe_title': 'Hardwood', 'transcript': '', 'alt': "They may technically have been softwoods at some point, but they definitely aren't now.", 'img': 'https://imgs.xkcd.com/comics/hardwood.png', 'title': 'Hardwood', 'day': '14'}
Arguments: ('latest_comic',)
[2025-02-17T18:01:07.123+0000] {taskinstance.py:1935} ERROR - Task failed with exception
Traceback (most recent call last):
  File "/home/airflow/.local/lib/python3.8/site-packages/airflow/operators/python.py", line 192, in execute
    return_value = self.execute_callable()
  File "/home/airflow/.local/lib/python3.8/site-packages/airflow/operators/python.py", line 209, in execute_callable
    return self.python_callable(*self.op_args, **self.op_kwargs)
  File "/opt/airflow/dags/xkcd-comics-dag.py", line 128, in fetch_all_comics
    stored_comic_id = get_latest_stored_comic_id()
  File "/opt/airflow/dags/xkcd-comics-dag.py", line 110, in get_latest_stored_comic_id
    cur.execute("SELECT MAX(comic_id) FROM xkcd_comics")
psycopg2.errors.UndefinedTable: relation "xkcd_comics" does not exist
LINE 1: SELECT MAX(comic_id) FROM xkcd_comics
                                  ^

[2025-02-17T18:01:07.127+0000] {taskinstance.py:1398} INFO - Marking task as UP_FOR_RETRY. dag_id=xkcd_comics, task_id=fetch_historical_comics, execution_date=20250217T180105, start_date=20250217T180106, end_date=20250217T180107
[2025-02-17T18:01:07.133+0000] {standard_task_runner.py:104} ERROR - Failed to execute job 5 for task fetch_historical_comics (relation "xkcd_comics" does not exist
LINE 1: SELECT MAX(comic_id) FROM xkcd_comics
                                  ^
; 561)
[2025-02-17T18:01:07.150+0000] {local_task_job_runner.py:228} INFO - Task exited with return code 1
[2025-02-17T18:01:07.159+0000] {taskinstance.py:2776} INFO - 0 downstream tasks scheduled from follow-on schedule check
