[2025-03-03T11:22:20.699+0000] {taskinstance.py:1157} INFO - Dependencies all met for dep_context=non-requeueable deps ti=<TaskInstance: xkcd_dbt_transformations.dbt_debug scheduled__2025-02-28T06:00:00+00:00 [queued]>
[2025-03-03T11:22:20.702+0000] {taskinstance.py:1157} INFO - Dependencies all met for dep_context=requeueable deps ti=<TaskInstance: xkcd_dbt_transformations.dbt_debug scheduled__2025-02-28T06:00:00+00:00 [queued]>
[2025-03-03T11:22:20.702+0000] {taskinstance.py:1359} INFO - Starting attempt 3 of 3
[2025-03-03T11:22:20.707+0000] {taskinstance.py:1380} INFO - Executing <Task(BashOperator): dbt_debug> on 2025-02-28 06:00:00+00:00
[2025-03-03T11:22:20.709+0000] {standard_task_runner.py:57} INFO - Started process 575 to run task
[2025-03-03T11:22:20.711+0000] {standard_task_runner.py:84} INFO - Running: ['***', 'tasks', 'run', 'xkcd_dbt_transformations', 'dbt_debug', 'scheduled__2025-02-28T06:00:00+00:00', '--job-id', '86', '--raw', '--subdir', 'DAGS_FOLDER/xkcd_dbt_transformations.py', '--cfg-path', '/tmp/tmpnre94nbt']
[2025-03-03T11:22:20.712+0000] {standard_task_runner.py:85} INFO - Job 86: Subtask dbt_debug
[2025-03-03T11:22:20.732+0000] {task_command.py:415} INFO - Running <TaskInstance: xkcd_dbt_transformations.dbt_debug scheduled__2025-02-28T06:00:00+00:00 [running]> on host 55c4a45e8eaa
[2025-03-03T11:22:20.759+0000] {taskinstance.py:1660} INFO - Exporting env vars: AIRFLOW_CTX_DAG_OWNER='***' AIRFLOW_CTX_DAG_ID='xkcd_dbt_transformations' AIRFLOW_CTX_TASK_ID='dbt_debug' AIRFLOW_CTX_EXECUTION_DATE='2025-02-28T06:00:00+00:00' AIRFLOW_CTX_TRY_NUMBER='3' AIRFLOW_CTX_DAG_RUN_ID='scheduled__2025-02-28T06:00:00+00:00'
[2025-03-03T11:22:20.759+0000] {subprocess.py:63} INFO - Tmp dir root location: /tmp
[2025-03-03T11:22:20.760+0000] {subprocess.py:75} INFO - Running command: ['/bin/bash', '-c', 'cd /opt/dbt && dbt debug --no-use-colors --no-version-check']
[2025-03-03T11:22:20.763+0000] {subprocess.py:86} INFO - Output:
[2025-03-03T11:22:22.187+0000] {subprocess.py:93} INFO - 11:22:22  Running with dbt=1.7.18
[2025-03-03T11:22:22.188+0000] {subprocess.py:93} INFO - 11:22:22  dbt version: 1.7.18
[2025-03-03T11:22:22.189+0000] {subprocess.py:93} INFO - 11:22:22  python version: 3.9.18
[2025-03-03T11:22:22.189+0000] {subprocess.py:93} INFO - 11:22:22  python path: /usr/local/bin/python
[2025-03-03T11:22:22.189+0000] {subprocess.py:93} INFO - 11:22:22  os info: Linux-6.10.14-linuxkit-aarch64-with-glibc2.31
[2025-03-03T11:22:22.250+0000] {subprocess.py:93} INFO - 11:22:22  Using profiles dir at /opt/dbt
[2025-03-03T11:22:22.251+0000] {subprocess.py:93} INFO - 11:22:22  Using profiles.yml file at /opt/dbt/profiles.yml
[2025-03-03T11:22:22.251+0000] {subprocess.py:93} INFO - 11:22:22  Using dbt_project.yml file at /opt/dbt/dbt_project.yml
[2025-03-03T11:22:22.252+0000] {subprocess.py:93} INFO - 11:22:22  adapter type: postgres
[2025-03-03T11:22:22.252+0000] {subprocess.py:93} INFO - 11:22:22  adapter version: 1.7.18
[2025-03-03T11:22:22.292+0000] {subprocess.py:93} INFO - 11:22:22  Configuration:
[2025-03-03T11:22:22.293+0000] {subprocess.py:93} INFO - 11:22:22    profiles.yml file [OK found and valid]
[2025-03-03T11:22:22.293+0000] {subprocess.py:93} INFO - 11:22:22    dbt_project.yml file [OK found and valid]
[2025-03-03T11:22:22.294+0000] {subprocess.py:93} INFO - 11:22:22  Required dependencies:
[2025-03-03T11:22:22.296+0000] {subprocess.py:93} INFO - 11:22:22   - git [ERROR]
[2025-03-03T11:22:22.296+0000] {subprocess.py:93} INFO - 
[2025-03-03T11:22:22.297+0000] {subprocess.py:93} INFO - 11:22:22  Connection:
[2025-03-03T11:22:22.297+0000] {subprocess.py:93} INFO - 11:22:22    host: postgres
[2025-03-03T11:22:22.298+0000] {subprocess.py:93} INFO - 11:22:22    port: 5432
[2025-03-03T11:22:22.298+0000] {subprocess.py:93} INFO - 11:22:22    user: ***
[2025-03-03T11:22:22.298+0000] {subprocess.py:93} INFO - 11:22:22    database: ***
[2025-03-03T11:22:22.299+0000] {subprocess.py:93} INFO - 11:22:22    schema: xkcd_dbt
[2025-03-03T11:22:22.299+0000] {subprocess.py:93} INFO - 11:22:22    connect_timeout: 10
[2025-03-03T11:22:22.299+0000] {subprocess.py:93} INFO - 11:22:22    role: None
[2025-03-03T11:22:22.300+0000] {subprocess.py:93} INFO - 11:22:22    search_path: None
[2025-03-03T11:22:22.300+0000] {subprocess.py:93} INFO - 11:22:22    keepalives_idle: 0
[2025-03-03T11:22:22.300+0000] {subprocess.py:93} INFO - 11:22:22    sslmode: None
[2025-03-03T11:22:22.301+0000] {subprocess.py:93} INFO - 11:22:22    sslcert: None
[2025-03-03T11:22:22.301+0000] {subprocess.py:93} INFO - 11:22:22    sslkey: None
[2025-03-03T11:22:22.302+0000] {subprocess.py:93} INFO - 11:22:22    sslrootcert: None
[2025-03-03T11:22:22.302+0000] {subprocess.py:93} INFO - 11:22:22    application_name: dbt
[2025-03-03T11:22:22.303+0000] {subprocess.py:93} INFO - 11:22:22    retries: 1
[2025-03-03T11:22:22.303+0000] {subprocess.py:93} INFO - 11:22:22  Registered adapter: postgres=1.7.18
[2025-03-03T11:22:22.309+0000] {subprocess.py:93} INFO - 11:22:22    Connection test: [OK connection ok]
[2025-03-03T11:22:22.309+0000] {subprocess.py:93} INFO - 
[2025-03-03T11:22:22.310+0000] {subprocess.py:93} INFO - 11:22:22  1 check failed:
[2025-03-03T11:22:22.310+0000] {subprocess.py:93} INFO - 11:22:22  Error from git --help: User does not have permissions for this command: "git"
[2025-03-03T11:22:22.310+0000] {subprocess.py:93} INFO - 
[2025-03-03T11:22:23.130+0000] {subprocess.py:97} INFO - Command exited with return code 1
[2025-03-03T11:22:23.136+0000] {taskinstance.py:1935} ERROR - Task failed with exception
Traceback (most recent call last):
  File "/home/airflow/.local/lib/python3.9/site-packages/airflow/operators/bash.py", line 210, in execute
    raise AirflowException(
airflow.exceptions.AirflowException: Bash command failed. The command returned a non-zero exit code 1.
[2025-03-03T11:22:23.138+0000] {taskinstance.py:1398} INFO - Marking task as FAILED. dag_id=xkcd_dbt_transformations, task_id=dbt_debug, execution_date=20250228T060000, start_date=20250303T112220, end_date=20250303T112223
[2025-03-03T11:22:23.143+0000] {standard_task_runner.py:104} ERROR - Failed to execute job 86 for task dbt_debug (Bash command failed. The command returned a non-zero exit code 1.; 575)
[2025-03-03T11:22:23.189+0000] {local_task_job_runner.py:228} INFO - Task exited with return code 1
[2025-03-03T11:22:23.199+0000] {taskinstance.py:2776} INFO - 0 downstream tasks scheduled from follow-on schedule check
