[2025-03-03T11:17:17.647+0000] {taskinstance.py:1157} INFO - Dependencies all met for dep_context=non-requeueable deps ti=<TaskInstance: xkcd_dbt_transformations.dbt_debug scheduled__2025-02-28T06:00:00+00:00 [queued]>
[2025-03-03T11:17:17.651+0000] {taskinstance.py:1157} INFO - Dependencies all met for dep_context=requeueable deps ti=<TaskInstance: xkcd_dbt_transformations.dbt_debug scheduled__2025-02-28T06:00:00+00:00 [queued]>
[2025-03-03T11:17:17.651+0000] {taskinstance.py:1359} INFO - Starting attempt 2 of 3
[2025-03-03T11:17:17.655+0000] {taskinstance.py:1380} INFO - Executing <Task(BashOperator): dbt_debug> on 2025-02-28 06:00:00+00:00
[2025-03-03T11:17:17.657+0000] {standard_task_runner.py:57} INFO - Started process 465 to run task
[2025-03-03T11:17:17.659+0000] {standard_task_runner.py:84} INFO - Running: ['***', 'tasks', 'run', 'xkcd_dbt_transformations', 'dbt_debug', 'scheduled__2025-02-28T06:00:00+00:00', '--job-id', '85', '--raw', '--subdir', 'DAGS_FOLDER/xkcd_dbt_transformations.py', '--cfg-path', '/tmp/tmp8tqljxhg']
[2025-03-03T11:17:17.660+0000] {standard_task_runner.py:85} INFO - Job 85: Subtask dbt_debug
[2025-03-03T11:17:17.678+0000] {task_command.py:415} INFO - Running <TaskInstance: xkcd_dbt_transformations.dbt_debug scheduled__2025-02-28T06:00:00+00:00 [running]> on host 55c4a45e8eaa
[2025-03-03T11:17:17.705+0000] {taskinstance.py:1660} INFO - Exporting env vars: AIRFLOW_CTX_DAG_OWNER='***' AIRFLOW_CTX_DAG_ID='xkcd_dbt_transformations' AIRFLOW_CTX_TASK_ID='dbt_debug' AIRFLOW_CTX_EXECUTION_DATE='2025-02-28T06:00:00+00:00' AIRFLOW_CTX_TRY_NUMBER='2' AIRFLOW_CTX_DAG_RUN_ID='scheduled__2025-02-28T06:00:00+00:00'
[2025-03-03T11:17:17.706+0000] {subprocess.py:63} INFO - Tmp dir root location: /tmp
[2025-03-03T11:17:17.706+0000] {subprocess.py:75} INFO - Running command: ['/bin/bash', '-c', 'cd /opt/dbt && dbt debug --no-use-colors --no-version-check']
[2025-03-03T11:17:17.709+0000] {subprocess.py:86} INFO - Output:
[2025-03-03T11:17:19.148+0000] {subprocess.py:93} INFO - 11:17:19  Running with dbt=1.7.18
[2025-03-03T11:17:19.150+0000] {subprocess.py:93} INFO - 11:17:19  dbt version: 1.7.18
[2025-03-03T11:17:19.150+0000] {subprocess.py:93} INFO - 11:17:19  python version: 3.9.18
[2025-03-03T11:17:19.150+0000] {subprocess.py:93} INFO - 11:17:19  python path: /usr/local/bin/python
[2025-03-03T11:17:19.151+0000] {subprocess.py:93} INFO - 11:17:19  os info: Linux-6.10.14-linuxkit-aarch64-with-glibc2.31
[2025-03-03T11:17:19.209+0000] {subprocess.py:93} INFO - 11:17:19  Using profiles dir at /opt/dbt
[2025-03-03T11:17:19.209+0000] {subprocess.py:93} INFO - 11:17:19  Using profiles.yml file at /opt/dbt/profiles.yml
[2025-03-03T11:17:19.210+0000] {subprocess.py:93} INFO - 11:17:19  Using dbt_project.yml file at /opt/dbt/dbt_project.yml
[2025-03-03T11:17:19.210+0000] {subprocess.py:93} INFO - 11:17:19  adapter type: postgres
[2025-03-03T11:17:19.210+0000] {subprocess.py:93} INFO - 11:17:19  adapter version: 1.7.18
[2025-03-03T11:17:19.250+0000] {subprocess.py:93} INFO - 11:17:19  Configuration:
[2025-03-03T11:17:19.250+0000] {subprocess.py:93} INFO - 11:17:19    profiles.yml file [OK found and valid]
[2025-03-03T11:17:19.250+0000] {subprocess.py:93} INFO - 11:17:19    dbt_project.yml file [OK found and valid]
[2025-03-03T11:17:19.251+0000] {subprocess.py:93} INFO - 11:17:19  Required dependencies:
[2025-03-03T11:17:19.253+0000] {subprocess.py:93} INFO - 11:17:19   - git [ERROR]
[2025-03-03T11:17:19.253+0000] {subprocess.py:93} INFO - 
[2025-03-03T11:17:19.254+0000] {subprocess.py:93} INFO - 11:17:19  Connection:
[2025-03-03T11:17:19.254+0000] {subprocess.py:93} INFO - 11:17:19    host: postgres
[2025-03-03T11:17:19.254+0000] {subprocess.py:93} INFO - 11:17:19    port: 5432
[2025-03-03T11:17:19.255+0000] {subprocess.py:93} INFO - 11:17:19    user: ***
[2025-03-03T11:17:19.255+0000] {subprocess.py:93} INFO - 11:17:19    database: ***
[2025-03-03T11:17:19.256+0000] {subprocess.py:93} INFO - 11:17:19    schema: xkcd_dbt
[2025-03-03T11:17:19.256+0000] {subprocess.py:93} INFO - 11:17:19    connect_timeout: 10
[2025-03-03T11:17:19.256+0000] {subprocess.py:93} INFO - 11:17:19    role: None
[2025-03-03T11:17:19.257+0000] {subprocess.py:93} INFO - 11:17:19    search_path: None
[2025-03-03T11:17:19.257+0000] {subprocess.py:93} INFO - 11:17:19    keepalives_idle: 0
[2025-03-03T11:17:19.257+0000] {subprocess.py:93} INFO - 11:17:19    sslmode: None
[2025-03-03T11:17:19.258+0000] {subprocess.py:93} INFO - 11:17:19    sslcert: None
[2025-03-03T11:17:19.258+0000] {subprocess.py:93} INFO - 11:17:19    sslkey: None
[2025-03-03T11:17:19.258+0000] {subprocess.py:93} INFO - 11:17:19    sslrootcert: None
[2025-03-03T11:17:19.259+0000] {subprocess.py:93} INFO - 11:17:19    application_name: dbt
[2025-03-03T11:17:19.259+0000] {subprocess.py:93} INFO - 11:17:19    retries: 1
[2025-03-03T11:17:19.260+0000] {subprocess.py:93} INFO - 11:17:19  Registered adapter: postgres=1.7.18
[2025-03-03T11:17:19.265+0000] {subprocess.py:93} INFO - 11:17:19    Connection test: [OK connection ok]
[2025-03-03T11:17:19.266+0000] {subprocess.py:93} INFO - 
[2025-03-03T11:17:19.266+0000] {subprocess.py:93} INFO - 11:17:19  1 check failed:
[2025-03-03T11:17:19.266+0000] {subprocess.py:93} INFO - 11:17:19  Error from git --help: User does not have permissions for this command: "git"
[2025-03-03T11:17:19.266+0000] {subprocess.py:93} INFO - 
[2025-03-03T11:17:20.052+0000] {subprocess.py:97} INFO - Command exited with return code 1
[2025-03-03T11:17:20.058+0000] {taskinstance.py:1935} ERROR - Task failed with exception
Traceback (most recent call last):
  File "/home/airflow/.local/lib/python3.9/site-packages/airflow/operators/bash.py", line 210, in execute
    raise AirflowException(
airflow.exceptions.AirflowException: Bash command failed. The command returned a non-zero exit code 1.
[2025-03-03T11:17:20.060+0000] {taskinstance.py:1398} INFO - Marking task as UP_FOR_RETRY. dag_id=xkcd_dbt_transformations, task_id=dbt_debug, execution_date=20250228T060000, start_date=20250303T111717, end_date=20250303T111720
[2025-03-03T11:17:20.066+0000] {standard_task_runner.py:104} ERROR - Failed to execute job 85 for task dbt_debug (Bash command failed. The command returned a non-zero exit code 1.; 465)
[2025-03-03T11:17:20.077+0000] {local_task_job_runner.py:228} INFO - Task exited with return code 1
[2025-03-03T11:17:20.088+0000] {taskinstance.py:2776} INFO - 0 downstream tasks scheduled from follow-on schedule check
