[2025-02-19T10:44:31.006+0000] {taskinstance.py:1157} INFO - Dependencies all met for dep_context=non-requeueable deps ti=<TaskInstance: xkcd_comics_ingestion.load_comics scheduled__2025-02-17T10:00:00+00:00 [queued]>
[2025-02-19T10:44:31.010+0000] {taskinstance.py:1157} INFO - Dependencies all met for dep_context=requeueable deps ti=<TaskInstance: xkcd_comics_ingestion.load_comics scheduled__2025-02-17T10:00:00+00:00 [queued]>
[2025-02-19T10:44:31.010+0000] {taskinstance.py:1359} INFO - Starting attempt 3 of 4
[2025-02-19T10:44:31.014+0000] {taskinstance.py:1380} INFO - Executing <Task(PythonOperator): load_comics> on 2025-02-17 10:00:00+00:00
[2025-02-19T10:44:31.016+0000] {standard_task_runner.py:57} INFO - Started process 2550 to run task
[2025-02-19T10:44:31.018+0000] {standard_task_runner.py:84} INFO - Running: ['***', 'tasks', 'run', 'xkcd_comics_ingestion', 'load_comics', 'scheduled__2025-02-17T10:00:00+00:00', '--job-id', '16', '--raw', '--subdir', 'DAGS_FOLDER/xkcd-comics-dag.py', '--cfg-path', '/tmp/tmpw2pgsp_j']
[2025-02-19T10:44:31.019+0000] {standard_task_runner.py:85} INFO - Job 16: Subtask load_comics
[2025-02-19T10:44:31.037+0000] {task_command.py:415} INFO - Running <TaskInstance: xkcd_comics_ingestion.load_comics scheduled__2025-02-17T10:00:00+00:00 [running]> on host a231dcd502c3
[2025-02-19T10:44:31.063+0000] {taskinstance.py:1660} INFO - Exporting env vars: AIRFLOW_CTX_DAG_OWNER='***' AIRFLOW_CTX_DAG_ID='xkcd_comics_ingestion' AIRFLOW_CTX_TASK_ID='load_comics' AIRFLOW_CTX_EXECUTION_DATE='2025-02-17T10:00:00+00:00' AIRFLOW_CTX_TRY_NUMBER='3' AIRFLOW_CTX_DAG_RUN_ID='scheduled__2025-02-17T10:00:00+00:00'
[2025-02-19T10:44:31.064+0000] {taskinstance.py:1935} ERROR - Task failed with exception
Traceback (most recent call last):
  File "/home/airflow/.local/lib/python3.9/site-packages/airflow/operators/python.py", line 192, in execute
    return_value = self.execute_callable()
  File "/home/airflow/.local/lib/python3.9/site-packages/airflow/operators/python.py", line 209, in execute_callable
    return self.python_callable(*self.op_args, **self.op_kwargs)
  File "/opt/airflow/dags/xkcd-comics-dag.py", line 147, in load_comics
    if latest_stored_id == 0:
NameError: name 'latest_stored_id' is not defined
[2025-02-19T10:44:31.067+0000] {taskinstance.py:1398} INFO - Marking task as UP_FOR_RETRY. dag_id=xkcd_comics_ingestion, task_id=load_comics, execution_date=20250217T100000, start_date=20250219T104431, end_date=20250219T104431
[2025-02-19T10:44:31.070+0000] {standard_task_runner.py:104} ERROR - Failed to execute job 16 for task load_comics (name 'latest_stored_id' is not defined; 2550)
[2025-02-19T10:44:31.081+0000] {local_task_job_runner.py:228} INFO - Task exited with return code 1
[2025-02-19T10:44:31.088+0000] {taskinstance.py:2776} INFO - 0 downstream tasks scheduled from follow-on schedule check
